Error while getting Updates: httpx.ReadError: 
No error handlers are registered, logging exception.
Traceback (most recent call last):
  File "/root/jupyter-env/lib/python3.12/site-packages/httpx/_transports/default.py", line 66, in map_httpcore_exceptions
    yield
  File "/root/jupyter-env/lib/python3.12/site-packages/httpx/_transports/default.py", line 366, in handle_async_request
    resp = await self._pool.handle_async_request(req)
           ^^^^^^^^^^^^^^^^^^^^^^^^^^^^^^^^^^^^^^^^^^
  File "/root/jupyter-env/lib/python3.12/site-packages/httpcore/_async/connection_pool.py", line 256, in handle_async_request
    raise exc from None
  File "/root/jupyter-env/lib/python3.12/site-packages/httpcore/_async/connection_pool.py", line 236, in handle_async_request
    response = await connection.handle_async_request(
               ^^^^^^^^^^^^^^^^^^^^^^^^^^^^^^^^^^^^^^
  File "/root/jupyter-env/lib/python3.12/site-packages/httpcore/_async/connection.py", line 103, in handle_async_request
    return await self._connection.handle_async_request(request)
           ^^^^^^^^^^^^^^^^^^^^^^^^^^^^^^^^^^^^^^^^^^^^^^^^^^^^
  File "/root/jupyter-env/lib/python3.12/site-packages/httpcore/_async/http11.py", line 136, in handle_async_request
    raise exc
  File "/root/jupyter-env/lib/python3.12/site-packages/httpcore/_async/http11.py", line 106, in handle_async_request
    ) = await self._receive_response_headers(**kwargs)
        ^^^^^^^^^^^^^^^^^^^^^^^^^^^^^^^^^^^^^^^^^^^^^^
  File "/root/jupyter-env/lib/python3.12/site-packages/httpcore/_async/http11.py", line 177, in _receive_response_headers
    event = await self._receive_event(timeout=timeout)
            ^^^^^^^^^^^^^^^^^^^^^^^^^^^^^^^^^^^^^^^^^^
  File "/root/jupyter-env/lib/python3.12/site-packages/httpcore/_async/http11.py", line 217, in _receive_event
    data = await self._network_stream.read(
           ^^^^^^^^^^^^^^^^^^^^^^^^^^^^^^^^
  File "/root/jupyter-env/lib/python3.12/site-packages/httpcore/_backends/anyio.py", line 32, in read
    with map_exceptions(exc_map):
  File "/usr/lib/python3.12/contextlib.py", line 158, in __exit__
    self.gen.throw(value)
  File "/root/jupyter-env/lib/python3.12/site-packages/httpcore/_exceptions.py", line 14, in map_exceptions
    raise to_exc(exc) from exc
httpcore.ReadError

The above exception was the direct cause of the following exception:

Traceback (most recent call last):
  File "/root/jupyter-env/lib/python3.12/site-packages/telegram/request/_httpxrequest.py", line 268, in do_request
    res = await self._client.request(
          ^^^^^^^^^^^^^^^^^^^^^^^^^^^
  File "/root/jupyter-env/lib/python3.12/site-packages/httpx/_client.py", line 1530, in request
    return await self.send(request, auth=auth, follow_redirects=follow_redirects)
           ^^^^^^^^^^^^^^^^^^^^^^^^^^^^^^^^^^^^^^^^^^^^^^^^^^^^^^^^^^^^^^^^^^^^^^
  File "/root/jupyter-env/lib/python3.12/site-packages/httpx/_client.py", line 1617, in send
    response = await self._send_handling_auth(
               ^^^^^^^^^^^^^^^^^^^^^^^^^^^^^^^
  File "/root/jupyter-env/lib/python3.12/site-packages/httpx/_client.py", line 1645, in _send_handling_auth
    response = await self._send_handling_redirects(
               ^^^^^^^^^^^^^^^^^^^^^^^^^^^^^^^^^^^^
  File "/root/jupyter-env/lib/python3.12/site-packages/httpx/_client.py", line 1682, in _send_handling_redirects
    response = await self._send_single_request(request)
               ^^^^^^^^^^^^^^^^^^^^^^^^^^^^^^^^^^^^^^^^
  File "/root/jupyter-env/lib/python3.12/site-packages/httpx/_client.py", line 1719, in _send_single_request
    response = await transport.handle_async_request(request)
               ^^^^^^^^^^^^^^^^^^^^^^^^^^^^^^^^^^^^^^^^^^^^^
  File "/root/jupyter-env/lib/python3.12/site-packages/httpx/_transports/default.py", line 365, in handle_async_request
    with map_httpcore_exceptions():
  File "/usr/lib/python3.12/contextlib.py", line 158, in __exit__
    self.gen.throw(value)
  File "/root/jupyter-env/lib/python3.12/site-packages/httpx/_transports/default.py", line 83, in map_httpcore_exceptions
    raise mapped_exc(message) from exc
httpx.ReadError

The above exception was the direct cause of the following exception:

Traceback (most recent call last):
  File "/root/jupyter-env/lib/python3.12/site-packages/telegram/ext/_updater.py", line 688, in _network_loop_retry
    if not await action_cb():
           ^^^^^^^^^^^^^^^^^
  File "/root/jupyter-env/lib/python3.12/site-packages/telegram/ext/_updater.py", line 384, in polling_action_cb
    raise exc
  File "/root/jupyter-env/lib/python3.12/site-packages/telegram/ext/_updater.py", line 373, in polling_action_cb
    updates = await self.bot.get_updates(
              ^^^^^^^^^^^^^^^^^^^^^^^^^^^
  File "/root/jupyter-env/lib/python3.12/site-packages/telegram/ext/_extbot.py", line 558, in get_updates
    updates = await super().get_updates(
              ^^^^^^^^^^^^^^^^^^^^^^^^^^
  File "/root/jupyter-env/lib/python3.12/site-packages/telegram/_bot.py", line 525, in decorator
    result = await func(self, *args, **kwargs)  # skipcq: PYL-E1102
             ^^^^^^^^^^^^^^^^^^^^^^^^^^^^^^^^^
  File "/root/jupyter-env/lib/python3.12/site-packages/telegram/_bot.py", line 3584, in get_updates
    await self._post(
  File "/root/jupyter-env/lib/python3.12/site-packages/telegram/_bot.py", line 613, in _post
    return await self._do_post(
           ^^^^^^^^^^^^^^^^^^^^
  File "/root/jupyter-env/lib/python3.12/site-packages/telegram/ext/_extbot.py", line 340, in _do_post
    return await super()._do_post(
           ^^^^^^^^^^^^^^^^^^^^^^^
  File "/root/jupyter-env/lib/python3.12/site-packages/telegram/_bot.py", line 641, in _do_post
    return await request.post(
           ^^^^^^^^^^^^^^^^^^^
  File "/root/jupyter-env/lib/python3.12/site-packages/telegram/request/_baserequest.py", line 200, in post
    result = await self._request_wrapper(
             ^^^^^^^^^^^^^^^^^^^^^^^^^^^^
  File "/root/jupyter-env/lib/python3.12/site-packages/telegram/request/_baserequest.py", line 340, in _request_wrapper
    raise exc
  File "/root/jupyter-env/lib/python3.12/site-packages/telegram/request/_baserequest.py", line 330, in _request_wrapper
    code, payload = await self.do_request(
                    ^^^^^^^^^^^^^^^^^^^^^^
  File "/root/jupyter-env/lib/python3.12/site-packages/telegram/request/_httpxrequest.py", line 292, in do_request
    raise NetworkError(f"httpx.{err.__class__.__name__}: {err}") from err
telegram.error.NetworkError: httpx.ReadError: 
No error handlers are registered, logging exception.
Traceback (most recent call last):
  File "/root/jupyter-env/lib/python3.12/site-packages/telegram/ext/_application.py", line 1234, in process_update
    await coroutine
  File "/root/jupyter-env/lib/python3.12/site-packages/telegram/ext/_basehandler.py", line 157, in handle_update
    return await self.callback(update, context)
           ^^^^^^^^^^^^^^^^^^^^^^^^^^^^^^^^^^^^
  File "/root/jupyter-env/project_outline/client_bot/keyboards/user_agreement.py", line 45, in agreement_button_handler
    reply_markup = get_main_menu()
                   ^^^^^^^^^^^^^^^
TypeError: get_main_menu() missing 1 required positional argument: 'user_choice'
Error while getting Updates: httpx.ReadError: 
No error handlers are registered, logging exception.
Traceback (most recent call last):
  File "/root/jupyter-env/lib/python3.12/site-packages/httpx/_transports/default.py", line 66, in map_httpcore_exceptions
    yield
  File "/root/jupyter-env/lib/python3.12/site-packages/httpx/_transports/default.py", line 366, in handle_async_request
    resp = await self._pool.handle_async_request(req)
           ^^^^^^^^^^^^^^^^^^^^^^^^^^^^^^^^^^^^^^^^^^
  File "/root/jupyter-env/lib/python3.12/site-packages/httpcore/_async/connection_pool.py", line 256, in handle_async_request
    raise exc from None
  File "/root/jupyter-env/lib/python3.12/site-packages/httpcore/_async/connection_pool.py", line 236, in handle_async_request
    response = await connection.handle_async_request(
               ^^^^^^^^^^^^^^^^^^^^^^^^^^^^^^^^^^^^^^
  File "/root/jupyter-env/lib/python3.12/site-packages/httpcore/_async/connection.py", line 103, in handle_async_request
    return await self._connection.handle_async_request(request)
           ^^^^^^^^^^^^^^^^^^^^^^^^^^^^^^^^^^^^^^^^^^^^^^^^^^^^
  File "/root/jupyter-env/lib/python3.12/site-packages/httpcore/_async/http11.py", line 136, in handle_async_request
    raise exc
  File "/root/jupyter-env/lib/python3.12/site-packages/httpcore/_async/http11.py", line 106, in handle_async_request
    ) = await self._receive_response_headers(**kwargs)
        ^^^^^^^^^^^^^^^^^^^^^^^^^^^^^^^^^^^^^^^^^^^^^^
  File "/root/jupyter-env/lib/python3.12/site-packages/httpcore/_async/http11.py", line 177, in _receive_response_headers
    event = await self._receive_event(timeout=timeout)
            ^^^^^^^^^^^^^^^^^^^^^^^^^^^^^^^^^^^^^^^^^^
  File "/root/jupyter-env/lib/python3.12/site-packages/httpcore/_async/http11.py", line 217, in _receive_event
    data = await self._network_stream.read(
           ^^^^^^^^^^^^^^^^^^^^^^^^^^^^^^^^
  File "/root/jupyter-env/lib/python3.12/site-packages/httpcore/_backends/anyio.py", line 32, in read
    with map_exceptions(exc_map):
  File "/usr/lib/python3.12/contextlib.py", line 158, in __exit__
    self.gen.throw(value)
  File "/root/jupyter-env/lib/python3.12/site-packages/httpcore/_exceptions.py", line 14, in map_exceptions
    raise to_exc(exc) from exc
httpcore.ReadError

The above exception was the direct cause of the following exception:

Traceback (most recent call last):
  File "/root/jupyter-env/lib/python3.12/site-packages/telegram/request/_httpxrequest.py", line 268, in do_request
    res = await self._client.request(
          ^^^^^^^^^^^^^^^^^^^^^^^^^^^
  File "/root/jupyter-env/lib/python3.12/site-packages/httpx/_client.py", line 1530, in request
    return await self.send(request, auth=auth, follow_redirects=follow_redirects)
           ^^^^^^^^^^^^^^^^^^^^^^^^^^^^^^^^^^^^^^^^^^^^^^^^^^^^^^^^^^^^^^^^^^^^^^
  File "/root/jupyter-env/lib/python3.12/site-packages/httpx/_client.py", line 1617, in send
    response = await self._send_handling_auth(
               ^^^^^^^^^^^^^^^^^^^^^^^^^^^^^^^
  File "/root/jupyter-env/lib/python3.12/site-packages/httpx/_client.py", line 1645, in _send_handling_auth
    response = await self._send_handling_redirects(
               ^^^^^^^^^^^^^^^^^^^^^^^^^^^^^^^^^^^^
  File "/root/jupyter-env/lib/python3.12/site-packages/httpx/_client.py", line 1682, in _send_handling_redirects
    response = await self._send_single_request(request)
               ^^^^^^^^^^^^^^^^^^^^^^^^^^^^^^^^^^^^^^^^
  File "/root/jupyter-env/lib/python3.12/site-packages/httpx/_client.py", line 1719, in _send_single_request
    response = await transport.handle_async_request(request)
               ^^^^^^^^^^^^^^^^^^^^^^^^^^^^^^^^^^^^^^^^^^^^^
  File "/root/jupyter-env/lib/python3.12/site-packages/httpx/_transports/default.py", line 365, in handle_async_request
    with map_httpcore_exceptions():
  File "/usr/lib/python3.12/contextlib.py", line 158, in __exit__
    self.gen.throw(value)
  File "/root/jupyter-env/lib/python3.12/site-packages/httpx/_transports/default.py", line 83, in map_httpcore_exceptions
    raise mapped_exc(message) from exc
httpx.ReadError

The above exception was the direct cause of the following exception:

Traceback (most recent call last):
  File "/root/jupyter-env/lib/python3.12/site-packages/telegram/ext/_updater.py", line 688, in _network_loop_retry
    if not await action_cb():
           ^^^^^^^^^^^^^^^^^
  File "/root/jupyter-env/lib/python3.12/site-packages/telegram/ext/_updater.py", line 384, in polling_action_cb
    raise exc
  File "/root/jupyter-env/lib/python3.12/site-packages/telegram/ext/_updater.py", line 373, in polling_action_cb
    updates = await self.bot.get_updates(
              ^^^^^^^^^^^^^^^^^^^^^^^^^^^
  File "/root/jupyter-env/lib/python3.12/site-packages/telegram/ext/_extbot.py", line 558, in get_updates
    updates = await super().get_updates(
              ^^^^^^^^^^^^^^^^^^^^^^^^^^
  File "/root/jupyter-env/lib/python3.12/site-packages/telegram/_bot.py", line 525, in decorator
    result = await func(self, *args, **kwargs)  # skipcq: PYL-E1102
             ^^^^^^^^^^^^^^^^^^^^^^^^^^^^^^^^^
  File "/root/jupyter-env/lib/python3.12/site-packages/telegram/_bot.py", line 3584, in get_updates
    await self._post(
  File "/root/jupyter-env/lib/python3.12/site-packages/telegram/_bot.py", line 613, in _post
    return await self._do_post(
           ^^^^^^^^^^^^^^^^^^^^
  File "/root/jupyter-env/lib/python3.12/site-packages/telegram/ext/_extbot.py", line 340, in _do_post
    return await super()._do_post(
           ^^^^^^^^^^^^^^^^^^^^^^^
  File "/root/jupyter-env/lib/python3.12/site-packages/telegram/_bot.py", line 641, in _do_post
    return await request.post(
           ^^^^^^^^^^^^^^^^^^^
  File "/root/jupyter-env/lib/python3.12/site-packages/telegram/request/_baserequest.py", line 200, in post
    result = await self._request_wrapper(
             ^^^^^^^^^^^^^^^^^^^^^^^^^^^^
  File "/root/jupyter-env/lib/python3.12/site-packages/telegram/request/_baserequest.py", line 340, in _request_wrapper
    raise exc
  File "/root/jupyter-env/lib/python3.12/site-packages/telegram/request/_baserequest.py", line 330, in _request_wrapper
    code, payload = await self.do_request(
                    ^^^^^^^^^^^^^^^^^^^^^^
  File "/root/jupyter-env/lib/python3.12/site-packages/telegram/request/_httpxrequest.py", line 292, in do_request
    raise NetworkError(f"httpx.{err.__class__.__name__}: {err}") from err
telegram.error.NetworkError: httpx.ReadError: 
Error while getting Updates: httpx.ReadError: 
No error handlers are registered, logging exception.
Traceback (most recent call last):
  File "/root/jupyter-env/lib/python3.12/site-packages/httpx/_transports/default.py", line 66, in map_httpcore_exceptions
    yield
  File "/root/jupyter-env/lib/python3.12/site-packages/httpx/_transports/default.py", line 366, in handle_async_request
    resp = await self._pool.handle_async_request(req)
           ^^^^^^^^^^^^^^^^^^^^^^^^^^^^^^^^^^^^^^^^^^
  File "/root/jupyter-env/lib/python3.12/site-packages/httpcore/_async/connection_pool.py", line 256, in handle_async_request
    raise exc from None
  File "/root/jupyter-env/lib/python3.12/site-packages/httpcore/_async/connection_pool.py", line 236, in handle_async_request
    response = await connection.handle_async_request(
               ^^^^^^^^^^^^^^^^^^^^^^^^^^^^^^^^^^^^^^
  File "/root/jupyter-env/lib/python3.12/site-packages/httpcore/_async/connection.py", line 103, in handle_async_request
    return await self._connection.handle_async_request(request)
           ^^^^^^^^^^^^^^^^^^^^^^^^^^^^^^^^^^^^^^^^^^^^^^^^^^^^
  File "/root/jupyter-env/lib/python3.12/site-packages/httpcore/_async/http11.py", line 136, in handle_async_request
    raise exc
  File "/root/jupyter-env/lib/python3.12/site-packages/httpcore/_async/http11.py", line 106, in handle_async_request
    ) = await self._receive_response_headers(**kwargs)
        ^^^^^^^^^^^^^^^^^^^^^^^^^^^^^^^^^^^^^^^^^^^^^^
  File "/root/jupyter-env/lib/python3.12/site-packages/httpcore/_async/http11.py", line 177, in _receive_response_headers
    event = await self._receive_event(timeout=timeout)
            ^^^^^^^^^^^^^^^^^^^^^^^^^^^^^^^^^^^^^^^^^^
  File "/root/jupyter-env/lib/python3.12/site-packages/httpcore/_async/http11.py", line 217, in _receive_event
    data = await self._network_stream.read(
           ^^^^^^^^^^^^^^^^^^^^^^^^^^^^^^^^
  File "/root/jupyter-env/lib/python3.12/site-packages/httpcore/_backends/anyio.py", line 32, in read
    with map_exceptions(exc_map):
  File "/usr/lib/python3.12/contextlib.py", line 158, in __exit__
    self.gen.throw(value)
  File "/root/jupyter-env/lib/python3.12/site-packages/httpcore/_exceptions.py", line 14, in map_exceptions
    raise to_exc(exc) from exc
httpcore.ReadError

The above exception was the direct cause of the following exception:

Traceback (most recent call last):
  File "/root/jupyter-env/lib/python3.12/site-packages/telegram/request/_httpxrequest.py", line 268, in do_request
    res = await self._client.request(
          ^^^^^^^^^^^^^^^^^^^^^^^^^^^
  File "/root/jupyter-env/lib/python3.12/site-packages/httpx/_client.py", line 1530, in request
    return await self.send(request, auth=auth, follow_redirects=follow_redirects)
           ^^^^^^^^^^^^^^^^^^^^^^^^^^^^^^^^^^^^^^^^^^^^^^^^^^^^^^^^^^^^^^^^^^^^^^
  File "/root/jupyter-env/lib/python3.12/site-packages/httpx/_client.py", line 1617, in send
    response = await self._send_handling_auth(
               ^^^^^^^^^^^^^^^^^^^^^^^^^^^^^^^
  File "/root/jupyter-env/lib/python3.12/site-packages/httpx/_client.py", line 1645, in _send_handling_auth
    response = await self._send_handling_redirects(
               ^^^^^^^^^^^^^^^^^^^^^^^^^^^^^^^^^^^^
  File "/root/jupyter-env/lib/python3.12/site-packages/httpx/_client.py", line 1682, in _send_handling_redirects
    response = await self._send_single_request(request)
               ^^^^^^^^^^^^^^^^^^^^^^^^^^^^^^^^^^^^^^^^
  File "/root/jupyter-env/lib/python3.12/site-packages/httpx/_client.py", line 1719, in _send_single_request
    response = await transport.handle_async_request(request)
               ^^^^^^^^^^^^^^^^^^^^^^^^^^^^^^^^^^^^^^^^^^^^^
  File "/root/jupyter-env/lib/python3.12/site-packages/httpx/_transports/default.py", line 365, in handle_async_request
    with map_httpcore_exceptions():
  File "/usr/lib/python3.12/contextlib.py", line 158, in __exit__
    self.gen.throw(value)
  File "/root/jupyter-env/lib/python3.12/site-packages/httpx/_transports/default.py", line 83, in map_httpcore_exceptions
    raise mapped_exc(message) from exc
httpx.ReadError

The above exception was the direct cause of the following exception:

Traceback (most recent call last):
  File "/root/jupyter-env/lib/python3.12/site-packages/telegram/ext/_updater.py", line 688, in _network_loop_retry
    if not await action_cb():
           ^^^^^^^^^^^^^^^^^
  File "/root/jupyter-env/lib/python3.12/site-packages/telegram/ext/_updater.py", line 384, in polling_action_cb
    raise exc
  File "/root/jupyter-env/lib/python3.12/site-packages/telegram/ext/_updater.py", line 373, in polling_action_cb
    updates = await self.bot.get_updates(
              ^^^^^^^^^^^^^^^^^^^^^^^^^^^
  File "/root/jupyter-env/lib/python3.12/site-packages/telegram/ext/_extbot.py", line 558, in get_updates
    updates = await super().get_updates(
              ^^^^^^^^^^^^^^^^^^^^^^^^^^
  File "/root/jupyter-env/lib/python3.12/site-packages/telegram/_bot.py", line 525, in decorator
    result = await func(self, *args, **kwargs)  # skipcq: PYL-E1102
             ^^^^^^^^^^^^^^^^^^^^^^^^^^^^^^^^^
  File "/root/jupyter-env/lib/python3.12/site-packages/telegram/_bot.py", line 3584, in get_updates
    await self._post(
  File "/root/jupyter-env/lib/python3.12/site-packages/telegram/_bot.py", line 613, in _post
    return await self._do_post(
           ^^^^^^^^^^^^^^^^^^^^
  File "/root/jupyter-env/lib/python3.12/site-packages/telegram/ext/_extbot.py", line 340, in _do_post
    return await super()._do_post(
           ^^^^^^^^^^^^^^^^^^^^^^^
  File "/root/jupyter-env/lib/python3.12/site-packages/telegram/_bot.py", line 641, in _do_post
    return await request.post(
           ^^^^^^^^^^^^^^^^^^^
  File "/root/jupyter-env/lib/python3.12/site-packages/telegram/request/_baserequest.py", line 200, in post
    result = await self._request_wrapper(
             ^^^^^^^^^^^^^^^^^^^^^^^^^^^^
  File "/root/jupyter-env/lib/python3.12/site-packages/telegram/request/_baserequest.py", line 340, in _request_wrapper
    raise exc
  File "/root/jupyter-env/lib/python3.12/site-packages/telegram/request/_baserequest.py", line 330, in _request_wrapper
    code, payload = await self.do_request(
                    ^^^^^^^^^^^^^^^^^^^^^^
  File "/root/jupyter-env/lib/python3.12/site-packages/telegram/request/_httpxrequest.py", line 292, in do_request
    raise NetworkError(f"httpx.{err.__class__.__name__}: {err}") from err
telegram.error.NetworkError: httpx.ReadError: 
Error while getting Updates: httpx.ReadError: 
No error handlers are registered, logging exception.
Traceback (most recent call last):
  File "/root/jupyter-env/lib/python3.12/site-packages/httpx/_transports/default.py", line 66, in map_httpcore_exceptions
    yield
  File "/root/jupyter-env/lib/python3.12/site-packages/httpx/_transports/default.py", line 366, in handle_async_request
    resp = await self._pool.handle_async_request(req)
           ^^^^^^^^^^^^^^^^^^^^^^^^^^^^^^^^^^^^^^^^^^
  File "/root/jupyter-env/lib/python3.12/site-packages/httpcore/_async/connection_pool.py", line 256, in handle_async_request
    raise exc from None
  File "/root/jupyter-env/lib/python3.12/site-packages/httpcore/_async/connection_pool.py", line 236, in handle_async_request
    response = await connection.handle_async_request(
               ^^^^^^^^^^^^^^^^^^^^^^^^^^^^^^^^^^^^^^
  File "/root/jupyter-env/lib/python3.12/site-packages/httpcore/_async/connection.py", line 103, in handle_async_request
    return await self._connection.handle_async_request(request)
           ^^^^^^^^^^^^^^^^^^^^^^^^^^^^^^^^^^^^^^^^^^^^^^^^^^^^
  File "/root/jupyter-env/lib/python3.12/site-packages/httpcore/_async/http11.py", line 136, in handle_async_request
    raise exc
  File "/root/jupyter-env/lib/python3.12/site-packages/httpcore/_async/http11.py", line 106, in handle_async_request
    ) = await self._receive_response_headers(**kwargs)
        ^^^^^^^^^^^^^^^^^^^^^^^^^^^^^^^^^^^^^^^^^^^^^^
  File "/root/jupyter-env/lib/python3.12/site-packages/httpcore/_async/http11.py", line 177, in _receive_response_headers
    event = await self._receive_event(timeout=timeout)
            ^^^^^^^^^^^^^^^^^^^^^^^^^^^^^^^^^^^^^^^^^^
  File "/root/jupyter-env/lib/python3.12/site-packages/httpcore/_async/http11.py", line 217, in _receive_event
    data = await self._network_stream.read(
           ^^^^^^^^^^^^^^^^^^^^^^^^^^^^^^^^
  File "/root/jupyter-env/lib/python3.12/site-packages/httpcore/_backends/anyio.py", line 32, in read
    with map_exceptions(exc_map):
  File "/usr/lib/python3.12/contextlib.py", line 158, in __exit__
    self.gen.throw(value)
  File "/root/jupyter-env/lib/python3.12/site-packages/httpcore/_exceptions.py", line 14, in map_exceptions
    raise to_exc(exc) from exc
httpcore.ReadError

The above exception was the direct cause of the following exception:

Traceback (most recent call last):
  File "/root/jupyter-env/lib/python3.12/site-packages/telegram/request/_httpxrequest.py", line 268, in do_request
    res = await self._client.request(
          ^^^^^^^^^^^^^^^^^^^^^^^^^^^
  File "/root/jupyter-env/lib/python3.12/site-packages/httpx/_client.py", line 1530, in request
    return await self.send(request, auth=auth, follow_redirects=follow_redirects)
           ^^^^^^^^^^^^^^^^^^^^^^^^^^^^^^^^^^^^^^^^^^^^^^^^^^^^^^^^^^^^^^^^^^^^^^
  File "/root/jupyter-env/lib/python3.12/site-packages/httpx/_client.py", line 1617, in send
    response = await self._send_handling_auth(
               ^^^^^^^^^^^^^^^^^^^^^^^^^^^^^^^
  File "/root/jupyter-env/lib/python3.12/site-packages/httpx/_client.py", line 1645, in _send_handling_auth
    response = await self._send_handling_redirects(
               ^^^^^^^^^^^^^^^^^^^^^^^^^^^^^^^^^^^^
  File "/root/jupyter-env/lib/python3.12/site-packages/httpx/_client.py", line 1682, in _send_handling_redirects
    response = await self._send_single_request(request)
               ^^^^^^^^^^^^^^^^^^^^^^^^^^^^^^^^^^^^^^^^
  File "/root/jupyter-env/lib/python3.12/site-packages/httpx/_client.py", line 1719, in _send_single_request
    response = await transport.handle_async_request(request)
               ^^^^^^^^^^^^^^^^^^^^^^^^^^^^^^^^^^^^^^^^^^^^^
  File "/root/jupyter-env/lib/python3.12/site-packages/httpx/_transports/default.py", line 365, in handle_async_request
    with map_httpcore_exceptions():
  File "/usr/lib/python3.12/contextlib.py", line 158, in __exit__
    self.gen.throw(value)
  File "/root/jupyter-env/lib/python3.12/site-packages/httpx/_transports/default.py", line 83, in map_httpcore_exceptions
    raise mapped_exc(message) from exc
httpx.ReadError

The above exception was the direct cause of the following exception:

Traceback (most recent call last):
  File "/root/jupyter-env/lib/python3.12/site-packages/telegram/ext/_updater.py", line 688, in _network_loop_retry
    if not await action_cb():
           ^^^^^^^^^^^^^^^^^
  File "/root/jupyter-env/lib/python3.12/site-packages/telegram/ext/_updater.py", line 384, in polling_action_cb
    raise exc
  File "/root/jupyter-env/lib/python3.12/site-packages/telegram/ext/_updater.py", line 373, in polling_action_cb
    updates = await self.bot.get_updates(
              ^^^^^^^^^^^^^^^^^^^^^^^^^^^
  File "/root/jupyter-env/lib/python3.12/site-packages/telegram/ext/_extbot.py", line 558, in get_updates
    updates = await super().get_updates(
              ^^^^^^^^^^^^^^^^^^^^^^^^^^
  File "/root/jupyter-env/lib/python3.12/site-packages/telegram/_bot.py", line 525, in decorator
    result = await func(self, *args, **kwargs)  # skipcq: PYL-E1102
             ^^^^^^^^^^^^^^^^^^^^^^^^^^^^^^^^^
  File "/root/jupyter-env/lib/python3.12/site-packages/telegram/_bot.py", line 3584, in get_updates
    await self._post(
  File "/root/jupyter-env/lib/python3.12/site-packages/telegram/_bot.py", line 613, in _post
    return await self._do_post(
           ^^^^^^^^^^^^^^^^^^^^
  File "/root/jupyter-env/lib/python3.12/site-packages/telegram/ext/_extbot.py", line 340, in _do_post
    return await super()._do_post(
           ^^^^^^^^^^^^^^^^^^^^^^^
  File "/root/jupyter-env/lib/python3.12/site-packages/telegram/_bot.py", line 641, in _do_post
    return await request.post(
           ^^^^^^^^^^^^^^^^^^^
  File "/root/jupyter-env/lib/python3.12/site-packages/telegram/request/_baserequest.py", line 200, in post
    result = await self._request_wrapper(
             ^^^^^^^^^^^^^^^^^^^^^^^^^^^^
  File "/root/jupyter-env/lib/python3.12/site-packages/telegram/request/_baserequest.py", line 340, in _request_wrapper
    raise exc
  File "/root/jupyter-env/lib/python3.12/site-packages/telegram/request/_baserequest.py", line 330, in _request_wrapper
    code, payload = await self.do_request(
                    ^^^^^^^^^^^^^^^^^^^^^^
  File "/root/jupyter-env/lib/python3.12/site-packages/telegram/request/_httpxrequest.py", line 292, in do_request
    raise NetworkError(f"httpx.{err.__class__.__name__}: {err}") from err
telegram.error.NetworkError: httpx.ReadError: 
Error while getting Updates: httpx.ReadError: 
No error handlers are registered, logging exception.
Traceback (most recent call last):
  File "/root/jupyter-env/lib/python3.12/site-packages/httpx/_transports/default.py", line 66, in map_httpcore_exceptions
    yield
  File "/root/jupyter-env/lib/python3.12/site-packages/httpx/_transports/default.py", line 366, in handle_async_request
    resp = await self._pool.handle_async_request(req)
           ^^^^^^^^^^^^^^^^^^^^^^^^^^^^^^^^^^^^^^^^^^
  File "/root/jupyter-env/lib/python3.12/site-packages/httpcore/_async/connection_pool.py", line 256, in handle_async_request
    raise exc from None
  File "/root/jupyter-env/lib/python3.12/site-packages/httpcore/_async/connection_pool.py", line 236, in handle_async_request
    response = await connection.handle_async_request(
               ^^^^^^^^^^^^^^^^^^^^^^^^^^^^^^^^^^^^^^
  File "/root/jupyter-env/lib/python3.12/site-packages/httpcore/_async/connection.py", line 103, in handle_async_request
    return await self._connection.handle_async_request(request)
           ^^^^^^^^^^^^^^^^^^^^^^^^^^^^^^^^^^^^^^^^^^^^^^^^^^^^
  File "/root/jupyter-env/lib/python3.12/site-packages/httpcore/_async/http11.py", line 136, in handle_async_request
    raise exc
  File "/root/jupyter-env/lib/python3.12/site-packages/httpcore/_async/http11.py", line 106, in handle_async_request
    ) = await self._receive_response_headers(**kwargs)
        ^^^^^^^^^^^^^^^^^^^^^^^^^^^^^^^^^^^^^^^^^^^^^^
  File "/root/jupyter-env/lib/python3.12/site-packages/httpcore/_async/http11.py", line 177, in _receive_response_headers
    event = await self._receive_event(timeout=timeout)
            ^^^^^^^^^^^^^^^^^^^^^^^^^^^^^^^^^^^^^^^^^^
  File "/root/jupyter-env/lib/python3.12/site-packages/httpcore/_async/http11.py", line 217, in _receive_event
    data = await self._network_stream.read(
           ^^^^^^^^^^^^^^^^^^^^^^^^^^^^^^^^
  File "/root/jupyter-env/lib/python3.12/site-packages/httpcore/_backends/anyio.py", line 32, in read
    with map_exceptions(exc_map):
  File "/usr/lib/python3.12/contextlib.py", line 158, in __exit__
    self.gen.throw(value)
  File "/root/jupyter-env/lib/python3.12/site-packages/httpcore/_exceptions.py", line 14, in map_exceptions
    raise to_exc(exc) from exc
httpcore.ReadError

The above exception was the direct cause of the following exception:

Traceback (most recent call last):
  File "/root/jupyter-env/lib/python3.12/site-packages/telegram/request/_httpxrequest.py", line 268, in do_request
    res = await self._client.request(
          ^^^^^^^^^^^^^^^^^^^^^^^^^^^
  File "/root/jupyter-env/lib/python3.12/site-packages/httpx/_client.py", line 1530, in request
    return await self.send(request, auth=auth, follow_redirects=follow_redirects)
           ^^^^^^^^^^^^^^^^^^^^^^^^^^^^^^^^^^^^^^^^^^^^^^^^^^^^^^^^^^^^^^^^^^^^^^
  File "/root/jupyter-env/lib/python3.12/site-packages/httpx/_client.py", line 1617, in send
    response = await self._send_handling_auth(
               ^^^^^^^^^^^^^^^^^^^^^^^^^^^^^^^
  File "/root/jupyter-env/lib/python3.12/site-packages/httpx/_client.py", line 1645, in _send_handling_auth
    response = await self._send_handling_redirects(
               ^^^^^^^^^^^^^^^^^^^^^^^^^^^^^^^^^^^^
  File "/root/jupyter-env/lib/python3.12/site-packages/httpx/_client.py", line 1682, in _send_handling_redirects
    response = await self._send_single_request(request)
               ^^^^^^^^^^^^^^^^^^^^^^^^^^^^^^^^^^^^^^^^
  File "/root/jupyter-env/lib/python3.12/site-packages/httpx/_client.py", line 1719, in _send_single_request
    response = await transport.handle_async_request(request)
               ^^^^^^^^^^^^^^^^^^^^^^^^^^^^^^^^^^^^^^^^^^^^^
  File "/root/jupyter-env/lib/python3.12/site-packages/httpx/_transports/default.py", line 365, in handle_async_request
    with map_httpcore_exceptions():
  File "/usr/lib/python3.12/contextlib.py", line 158, in __exit__
    self.gen.throw(value)
  File "/root/jupyter-env/lib/python3.12/site-packages/httpx/_transports/default.py", line 83, in map_httpcore_exceptions
    raise mapped_exc(message) from exc
httpx.ReadError

The above exception was the direct cause of the following exception:

Traceback (most recent call last):
  File "/root/jupyter-env/lib/python3.12/site-packages/telegram/ext/_updater.py", line 688, in _network_loop_retry
    if not await action_cb():
           ^^^^^^^^^^^^^^^^^
  File "/root/jupyter-env/lib/python3.12/site-packages/telegram/ext/_updater.py", line 384, in polling_action_cb
    raise exc
  File "/root/jupyter-env/lib/python3.12/site-packages/telegram/ext/_updater.py", line 373, in polling_action_cb
    updates = await self.bot.get_updates(
              ^^^^^^^^^^^^^^^^^^^^^^^^^^^
  File "/root/jupyter-env/lib/python3.12/site-packages/telegram/ext/_extbot.py", line 558, in get_updates
    updates = await super().get_updates(
              ^^^^^^^^^^^^^^^^^^^^^^^^^^
  File "/root/jupyter-env/lib/python3.12/site-packages/telegram/_bot.py", line 525, in decorator
    result = await func(self, *args, **kwargs)  # skipcq: PYL-E1102
             ^^^^^^^^^^^^^^^^^^^^^^^^^^^^^^^^^
  File "/root/jupyter-env/lib/python3.12/site-packages/telegram/_bot.py", line 3584, in get_updates
    await self._post(
  File "/root/jupyter-env/lib/python3.12/site-packages/telegram/_bot.py", line 613, in _post
    return await self._do_post(
           ^^^^^^^^^^^^^^^^^^^^
  File "/root/jupyter-env/lib/python3.12/site-packages/telegram/ext/_extbot.py", line 340, in _do_post
    return await super()._do_post(
           ^^^^^^^^^^^^^^^^^^^^^^^
  File "/root/jupyter-env/lib/python3.12/site-packages/telegram/_bot.py", line 641, in _do_post
    return await request.post(
           ^^^^^^^^^^^^^^^^^^^
  File "/root/jupyter-env/lib/python3.12/site-packages/telegram/request/_baserequest.py", line 200, in post
    result = await self._request_wrapper(
             ^^^^^^^^^^^^^^^^^^^^^^^^^^^^
  File "/root/jupyter-env/lib/python3.12/site-packages/telegram/request/_baserequest.py", line 340, in _request_wrapper
    raise exc
  File "/root/jupyter-env/lib/python3.12/site-packages/telegram/request/_baserequest.py", line 330, in _request_wrapper
    code, payload = await self.do_request(
                    ^^^^^^^^^^^^^^^^^^^^^^
  File "/root/jupyter-env/lib/python3.12/site-packages/telegram/request/_httpxrequest.py", line 292, in do_request
    raise NetworkError(f"httpx.{err.__class__.__name__}: {err}") from err
telegram.error.NetworkError: httpx.ReadError: 
Error while getting Updates: httpx.ReadError: 
No error handlers are registered, logging exception.
Traceback (most recent call last):
  File "/root/jupyter-env/lib/python3.12/site-packages/httpx/_transports/default.py", line 66, in map_httpcore_exceptions
    yield
  File "/root/jupyter-env/lib/python3.12/site-packages/httpx/_transports/default.py", line 366, in handle_async_request
    resp = await self._pool.handle_async_request(req)
           ^^^^^^^^^^^^^^^^^^^^^^^^^^^^^^^^^^^^^^^^^^
  File "/root/jupyter-env/lib/python3.12/site-packages/httpcore/_async/connection_pool.py", line 256, in handle_async_request
    raise exc from None
  File "/root/jupyter-env/lib/python3.12/site-packages/httpcore/_async/connection_pool.py", line 236, in handle_async_request
    response = await connection.handle_async_request(
               ^^^^^^^^^^^^^^^^^^^^^^^^^^^^^^^^^^^^^^
  File "/root/jupyter-env/lib/python3.12/site-packages/httpcore/_async/connection.py", line 103, in handle_async_request
    return await self._connection.handle_async_request(request)
           ^^^^^^^^^^^^^^^^^^^^^^^^^^^^^^^^^^^^^^^^^^^^^^^^^^^^
  File "/root/jupyter-env/lib/python3.12/site-packages/httpcore/_async/http11.py", line 136, in handle_async_request
    raise exc
  File "/root/jupyter-env/lib/python3.12/site-packages/httpcore/_async/http11.py", line 106, in handle_async_request
    ) = await self._receive_response_headers(**kwargs)
        ^^^^^^^^^^^^^^^^^^^^^^^^^^^^^^^^^^^^^^^^^^^^^^
  File "/root/jupyter-env/lib/python3.12/site-packages/httpcore/_async/http11.py", line 177, in _receive_response_headers
    event = await self._receive_event(timeout=timeout)
            ^^^^^^^^^^^^^^^^^^^^^^^^^^^^^^^^^^^^^^^^^^
  File "/root/jupyter-env/lib/python3.12/site-packages/httpcore/_async/http11.py", line 217, in _receive_event
    data = await self._network_stream.read(
           ^^^^^^^^^^^^^^^^^^^^^^^^^^^^^^^^
  File "/root/jupyter-env/lib/python3.12/site-packages/httpcore/_backends/anyio.py", line 32, in read
    with map_exceptions(exc_map):
  File "/usr/lib/python3.12/contextlib.py", line 158, in __exit__
    self.gen.throw(value)
  File "/root/jupyter-env/lib/python3.12/site-packages/httpcore/_exceptions.py", line 14, in map_exceptions
    raise to_exc(exc) from exc
httpcore.ReadError

The above exception was the direct cause of the following exception:

Traceback (most recent call last):
  File "/root/jupyter-env/lib/python3.12/site-packages/telegram/request/_httpxrequest.py", line 268, in do_request
    res = await self._client.request(
          ^^^^^^^^^^^^^^^^^^^^^^^^^^^
  File "/root/jupyter-env/lib/python3.12/site-packages/httpx/_client.py", line 1530, in request
    return await self.send(request, auth=auth, follow_redirects=follow_redirects)
           ^^^^^^^^^^^^^^^^^^^^^^^^^^^^^^^^^^^^^^^^^^^^^^^^^^^^^^^^^^^^^^^^^^^^^^
  File "/root/jupyter-env/lib/python3.12/site-packages/httpx/_client.py", line 1617, in send
    response = await self._send_handling_auth(
               ^^^^^^^^^^^^^^^^^^^^^^^^^^^^^^^
  File "/root/jupyter-env/lib/python3.12/site-packages/httpx/_client.py", line 1645, in _send_handling_auth
    response = await self._send_handling_redirects(
               ^^^^^^^^^^^^^^^^^^^^^^^^^^^^^^^^^^^^
  File "/root/jupyter-env/lib/python3.12/site-packages/httpx/_client.py", line 1682, in _send_handling_redirects
    response = await self._send_single_request(request)
               ^^^^^^^^^^^^^^^^^^^^^^^^^^^^^^^^^^^^^^^^
  File "/root/jupyter-env/lib/python3.12/site-packages/httpx/_client.py", line 1719, in _send_single_request
    response = await transport.handle_async_request(request)
               ^^^^^^^^^^^^^^^^^^^^^^^^^^^^^^^^^^^^^^^^^^^^^
  File "/root/jupyter-env/lib/python3.12/site-packages/httpx/_transports/default.py", line 365, in handle_async_request
    with map_httpcore_exceptions():
  File "/usr/lib/python3.12/contextlib.py", line 158, in __exit__
    self.gen.throw(value)
  File "/root/jupyter-env/lib/python3.12/site-packages/httpx/_transports/default.py", line 83, in map_httpcore_exceptions
    raise mapped_exc(message) from exc
httpx.ReadError

The above exception was the direct cause of the following exception:

Traceback (most recent call last):
  File "/root/jupyter-env/lib/python3.12/site-packages/telegram/ext/_updater.py", line 688, in _network_loop_retry
    if not await action_cb():
           ^^^^^^^^^^^^^^^^^
  File "/root/jupyter-env/lib/python3.12/site-packages/telegram/ext/_updater.py", line 384, in polling_action_cb
    raise exc
  File "/root/jupyter-env/lib/python3.12/site-packages/telegram/ext/_updater.py", line 373, in polling_action_cb
    updates = await self.bot.get_updates(
              ^^^^^^^^^^^^^^^^^^^^^^^^^^^
  File "/root/jupyter-env/lib/python3.12/site-packages/telegram/ext/_extbot.py", line 558, in get_updates
    updates = await super().get_updates(
              ^^^^^^^^^^^^^^^^^^^^^^^^^^
  File "/root/jupyter-env/lib/python3.12/site-packages/telegram/_bot.py", line 525, in decorator
    result = await func(self, *args, **kwargs)  # skipcq: PYL-E1102
             ^^^^^^^^^^^^^^^^^^^^^^^^^^^^^^^^^
  File "/root/jupyter-env/lib/python3.12/site-packages/telegram/_bot.py", line 3584, in get_updates
    await self._post(
  File "/root/jupyter-env/lib/python3.12/site-packages/telegram/_bot.py", line 613, in _post
    return await self._do_post(
           ^^^^^^^^^^^^^^^^^^^^
  File "/root/jupyter-env/lib/python3.12/site-packages/telegram/ext/_extbot.py", line 340, in _do_post
    return await super()._do_post(
           ^^^^^^^^^^^^^^^^^^^^^^^
  File "/root/jupyter-env/lib/python3.12/site-packages/telegram/_bot.py", line 641, in _do_post
    return await request.post(
           ^^^^^^^^^^^^^^^^^^^
  File "/root/jupyter-env/lib/python3.12/site-packages/telegram/request/_baserequest.py", line 200, in post
    result = await self._request_wrapper(
             ^^^^^^^^^^^^^^^^^^^^^^^^^^^^
  File "/root/jupyter-env/lib/python3.12/site-packages/telegram/request/_baserequest.py", line 340, in _request_wrapper
    raise exc
  File "/root/jupyter-env/lib/python3.12/site-packages/telegram/request/_baserequest.py", line 330, in _request_wrapper
    code, payload = await self.do_request(
                    ^^^^^^^^^^^^^^^^^^^^^^
  File "/root/jupyter-env/lib/python3.12/site-packages/telegram/request/_httpxrequest.py", line 292, in do_request
    raise NetworkError(f"httpx.{err.__class__.__name__}: {err}") from err
telegram.error.NetworkError: httpx.ReadError: 
Error while getting Updates: httpx.ReadError: 
No error handlers are registered, logging exception.
Traceback (most recent call last):
  File "/root/jupyter-env/lib/python3.12/site-packages/httpx/_transports/default.py", line 66, in map_httpcore_exceptions
    yield
  File "/root/jupyter-env/lib/python3.12/site-packages/httpx/_transports/default.py", line 366, in handle_async_request
    resp = await self._pool.handle_async_request(req)
           ^^^^^^^^^^^^^^^^^^^^^^^^^^^^^^^^^^^^^^^^^^
  File "/root/jupyter-env/lib/python3.12/site-packages/httpcore/_async/connection_pool.py", line 256, in handle_async_request
    raise exc from None
  File "/root/jupyter-env/lib/python3.12/site-packages/httpcore/_async/connection_pool.py", line 236, in handle_async_request
    response = await connection.handle_async_request(
               ^^^^^^^^^^^^^^^^^^^^^^^^^^^^^^^^^^^^^^
  File "/root/jupyter-env/lib/python3.12/site-packages/httpcore/_async/connection.py", line 103, in handle_async_request
    return await self._connection.handle_async_request(request)
           ^^^^^^^^^^^^^^^^^^^^^^^^^^^^^^^^^^^^^^^^^^^^^^^^^^^^
  File "/root/jupyter-env/lib/python3.12/site-packages/httpcore/_async/http11.py", line 136, in handle_async_request
    raise exc
  File "/root/jupyter-env/lib/python3.12/site-packages/httpcore/_async/http11.py", line 106, in handle_async_request
    ) = await self._receive_response_headers(**kwargs)
        ^^^^^^^^^^^^^^^^^^^^^^^^^^^^^^^^^^^^^^^^^^^^^^
  File "/root/jupyter-env/lib/python3.12/site-packages/httpcore/_async/http11.py", line 177, in _receive_response_headers
    event = await self._receive_event(timeout=timeout)
            ^^^^^^^^^^^^^^^^^^^^^^^^^^^^^^^^^^^^^^^^^^
  File "/root/jupyter-env/lib/python3.12/site-packages/httpcore/_async/http11.py", line 217, in _receive_event
    data = await self._network_stream.read(
           ^^^^^^^^^^^^^^^^^^^^^^^^^^^^^^^^
  File "/root/jupyter-env/lib/python3.12/site-packages/httpcore/_backends/anyio.py", line 32, in read
    with map_exceptions(exc_map):
  File "/usr/lib/python3.12/contextlib.py", line 158, in __exit__
    self.gen.throw(value)
  File "/root/jupyter-env/lib/python3.12/site-packages/httpcore/_exceptions.py", line 14, in map_exceptions
    raise to_exc(exc) from exc
httpcore.ReadError

The above exception was the direct cause of the following exception:

Traceback (most recent call last):
  File "/root/jupyter-env/lib/python3.12/site-packages/telegram/request/_httpxrequest.py", line 268, in do_request
    res = await self._client.request(
          ^^^^^^^^^^^^^^^^^^^^^^^^^^^
  File "/root/jupyter-env/lib/python3.12/site-packages/httpx/_client.py", line 1530, in request
    return await self.send(request, auth=auth, follow_redirects=follow_redirects)
           ^^^^^^^^^^^^^^^^^^^^^^^^^^^^^^^^^^^^^^^^^^^^^^^^^^^^^^^^^^^^^^^^^^^^^^
  File "/root/jupyter-env/lib/python3.12/site-packages/httpx/_client.py", line 1617, in send
    response = await self._send_handling_auth(
               ^^^^^^^^^^^^^^^^^^^^^^^^^^^^^^^
  File "/root/jupyter-env/lib/python3.12/site-packages/httpx/_client.py", line 1645, in _send_handling_auth
    response = await self._send_handling_redirects(
               ^^^^^^^^^^^^^^^^^^^^^^^^^^^^^^^^^^^^
  File "/root/jupyter-env/lib/python3.12/site-packages/httpx/_client.py", line 1682, in _send_handling_redirects
    response = await self._send_single_request(request)
               ^^^^^^^^^^^^^^^^^^^^^^^^^^^^^^^^^^^^^^^^
  File "/root/jupyter-env/lib/python3.12/site-packages/httpx/_client.py", line 1719, in _send_single_request
    response = await transport.handle_async_request(request)
               ^^^^^^^^^^^^^^^^^^^^^^^^^^^^^^^^^^^^^^^^^^^^^
  File "/root/jupyter-env/lib/python3.12/site-packages/httpx/_transports/default.py", line 365, in handle_async_request
    with map_httpcore_exceptions():
  File "/usr/lib/python3.12/contextlib.py", line 158, in __exit__
    self.gen.throw(value)
  File "/root/jupyter-env/lib/python3.12/site-packages/httpx/_transports/default.py", line 83, in map_httpcore_exceptions
    raise mapped_exc(message) from exc
httpx.ReadError

The above exception was the direct cause of the following exception:

Traceback (most recent call last):
  File "/root/jupyter-env/lib/python3.12/site-packages/telegram/ext/_updater.py", line 688, in _network_loop_retry
    if not await action_cb():
           ^^^^^^^^^^^^^^^^^
  File "/root/jupyter-env/lib/python3.12/site-packages/telegram/ext/_updater.py", line 384, in polling_action_cb
    raise exc
  File "/root/jupyter-env/lib/python3.12/site-packages/telegram/ext/_updater.py", line 373, in polling_action_cb
    updates = await self.bot.get_updates(
              ^^^^^^^^^^^^^^^^^^^^^^^^^^^
  File "/root/jupyter-env/lib/python3.12/site-packages/telegram/ext/_extbot.py", line 558, in get_updates
    updates = await super().get_updates(
              ^^^^^^^^^^^^^^^^^^^^^^^^^^
  File "/root/jupyter-env/lib/python3.12/site-packages/telegram/_bot.py", line 525, in decorator
    result = await func(self, *args, **kwargs)  # skipcq: PYL-E1102
             ^^^^^^^^^^^^^^^^^^^^^^^^^^^^^^^^^
  File "/root/jupyter-env/lib/python3.12/site-packages/telegram/_bot.py", line 3584, in get_updates
    await self._post(
  File "/root/jupyter-env/lib/python3.12/site-packages/telegram/_bot.py", line 613, in _post
    return await self._do_post(
           ^^^^^^^^^^^^^^^^^^^^
  File "/root/jupyter-env/lib/python3.12/site-packages/telegram/ext/_extbot.py", line 340, in _do_post
    return await super()._do_post(
           ^^^^^^^^^^^^^^^^^^^^^^^
  File "/root/jupyter-env/lib/python3.12/site-packages/telegram/_bot.py", line 641, in _do_post
    return await request.post(
           ^^^^^^^^^^^^^^^^^^^
  File "/root/jupyter-env/lib/python3.12/site-packages/telegram/request/_baserequest.py", line 200, in post
    result = await self._request_wrapper(
             ^^^^^^^^^^^^^^^^^^^^^^^^^^^^
  File "/root/jupyter-env/lib/python3.12/site-packages/telegram/request/_baserequest.py", line 340, in _request_wrapper
    raise exc
  File "/root/jupyter-env/lib/python3.12/site-packages/telegram/request/_baserequest.py", line 330, in _request_wrapper
    code, payload = await self.do_request(
                    ^^^^^^^^^^^^^^^^^^^^^^
  File "/root/jupyter-env/lib/python3.12/site-packages/telegram/request/_httpxrequest.py", line 292, in do_request
    raise NetworkError(f"httpx.{err.__class__.__name__}: {err}") from err
telegram.error.NetworkError: httpx.ReadError: 
Error while getting Updates: httpx.ReadError: 
No error handlers are registered, logging exception.
Traceback (most recent call last):
  File "/root/jupyter-env/lib/python3.12/site-packages/httpx/_transports/default.py", line 66, in map_httpcore_exceptions
    yield
  File "/root/jupyter-env/lib/python3.12/site-packages/httpx/_transports/default.py", line 366, in handle_async_request
    resp = await self._pool.handle_async_request(req)
           ^^^^^^^^^^^^^^^^^^^^^^^^^^^^^^^^^^^^^^^^^^
  File "/root/jupyter-env/lib/python3.12/site-packages/httpcore/_async/connection_pool.py", line 256, in handle_async_request
    raise exc from None
  File "/root/jupyter-env/lib/python3.12/site-packages/httpcore/_async/connection_pool.py", line 236, in handle_async_request
    response = await connection.handle_async_request(
               ^^^^^^^^^^^^^^^^^^^^^^^^^^^^^^^^^^^^^^
  File "/root/jupyter-env/lib/python3.12/site-packages/httpcore/_async/connection.py", line 103, in handle_async_request
    return await self._connection.handle_async_request(request)
           ^^^^^^^^^^^^^^^^^^^^^^^^^^^^^^^^^^^^^^^^^^^^^^^^^^^^
  File "/root/jupyter-env/lib/python3.12/site-packages/httpcore/_async/http11.py", line 136, in handle_async_request
    raise exc
  File "/root/jupyter-env/lib/python3.12/site-packages/httpcore/_async/http11.py", line 106, in handle_async_request
    ) = await self._receive_response_headers(**kwargs)
        ^^^^^^^^^^^^^^^^^^^^^^^^^^^^^^^^^^^^^^^^^^^^^^
  File "/root/jupyter-env/lib/python3.12/site-packages/httpcore/_async/http11.py", line 177, in _receive_response_headers
    event = await self._receive_event(timeout=timeout)
            ^^^^^^^^^^^^^^^^^^^^^^^^^^^^^^^^^^^^^^^^^^
  File "/root/jupyter-env/lib/python3.12/site-packages/httpcore/_async/http11.py", line 217, in _receive_event
    data = await self._network_stream.read(
           ^^^^^^^^^^^^^^^^^^^^^^^^^^^^^^^^
  File "/root/jupyter-env/lib/python3.12/site-packages/httpcore/_backends/anyio.py", line 32, in read
    with map_exceptions(exc_map):
  File "/usr/lib/python3.12/contextlib.py", line 158, in __exit__
    self.gen.throw(value)
  File "/root/jupyter-env/lib/python3.12/site-packages/httpcore/_exceptions.py", line 14, in map_exceptions
    raise to_exc(exc) from exc
httpcore.ReadError

The above exception was the direct cause of the following exception:

Traceback (most recent call last):
  File "/root/jupyter-env/lib/python3.12/site-packages/telegram/request/_httpxrequest.py", line 268, in do_request
    res = await self._client.request(
          ^^^^^^^^^^^^^^^^^^^^^^^^^^^
  File "/root/jupyter-env/lib/python3.12/site-packages/httpx/_client.py", line 1530, in request
    return await self.send(request, auth=auth, follow_redirects=follow_redirects)
           ^^^^^^^^^^^^^^^^^^^^^^^^^^^^^^^^^^^^^^^^^^^^^^^^^^^^^^^^^^^^^^^^^^^^^^
  File "/root/jupyter-env/lib/python3.12/site-packages/httpx/_client.py", line 1617, in send
    response = await self._send_handling_auth(
               ^^^^^^^^^^^^^^^^^^^^^^^^^^^^^^^
  File "/root/jupyter-env/lib/python3.12/site-packages/httpx/_client.py", line 1645, in _send_handling_auth
    response = await self._send_handling_redirects(
               ^^^^^^^^^^^^^^^^^^^^^^^^^^^^^^^^^^^^
  File "/root/jupyter-env/lib/python3.12/site-packages/httpx/_client.py", line 1682, in _send_handling_redirects
    response = await self._send_single_request(request)
               ^^^^^^^^^^^^^^^^^^^^^^^^^^^^^^^^^^^^^^^^
  File "/root/jupyter-env/lib/python3.12/site-packages/httpx/_client.py", line 1719, in _send_single_request
    response = await transport.handle_async_request(request)
               ^^^^^^^^^^^^^^^^^^^^^^^^^^^^^^^^^^^^^^^^^^^^^
  File "/root/jupyter-env/lib/python3.12/site-packages/httpx/_transports/default.py", line 365, in handle_async_request
    with map_httpcore_exceptions():
  File "/usr/lib/python3.12/contextlib.py", line 158, in __exit__
    self.gen.throw(value)
  File "/root/jupyter-env/lib/python3.12/site-packages/httpx/_transports/default.py", line 83, in map_httpcore_exceptions
    raise mapped_exc(message) from exc
httpx.ReadError

The above exception was the direct cause of the following exception:

Traceback (most recent call last):
  File "/root/jupyter-env/lib/python3.12/site-packages/telegram/ext/_updater.py", line 688, in _network_loop_retry
    if not await action_cb():
           ^^^^^^^^^^^^^^^^^
  File "/root/jupyter-env/lib/python3.12/site-packages/telegram/ext/_updater.py", line 384, in polling_action_cb
    raise exc
  File "/root/jupyter-env/lib/python3.12/site-packages/telegram/ext/_updater.py", line 373, in polling_action_cb
    updates = await self.bot.get_updates(
              ^^^^^^^^^^^^^^^^^^^^^^^^^^^
  File "/root/jupyter-env/lib/python3.12/site-packages/telegram/ext/_extbot.py", line 558, in get_updates
    updates = await super().get_updates(
              ^^^^^^^^^^^^^^^^^^^^^^^^^^
  File "/root/jupyter-env/lib/python3.12/site-packages/telegram/_bot.py", line 525, in decorator
    result = await func(self, *args, **kwargs)  # skipcq: PYL-E1102
             ^^^^^^^^^^^^^^^^^^^^^^^^^^^^^^^^^
  File "/root/jupyter-env/lib/python3.12/site-packages/telegram/_bot.py", line 3584, in get_updates
    await self._post(
  File "/root/jupyter-env/lib/python3.12/site-packages/telegram/_bot.py", line 613, in _post
    return await self._do_post(
           ^^^^^^^^^^^^^^^^^^^^
  File "/root/jupyter-env/lib/python3.12/site-packages/telegram/ext/_extbot.py", line 340, in _do_post
    return await super()._do_post(
           ^^^^^^^^^^^^^^^^^^^^^^^
  File "/root/jupyter-env/lib/python3.12/site-packages/telegram/_bot.py", line 641, in _do_post
    return await request.post(
           ^^^^^^^^^^^^^^^^^^^
  File "/root/jupyter-env/lib/python3.12/site-packages/telegram/request/_baserequest.py", line 200, in post
    result = await self._request_wrapper(
             ^^^^^^^^^^^^^^^^^^^^^^^^^^^^
  File "/root/jupyter-env/lib/python3.12/site-packages/telegram/request/_baserequest.py", line 340, in _request_wrapper
    raise exc
  File "/root/jupyter-env/lib/python3.12/site-packages/telegram/request/_baserequest.py", line 330, in _request_wrapper
    code, payload = await self.do_request(
                    ^^^^^^^^^^^^^^^^^^^^^^
  File "/root/jupyter-env/lib/python3.12/site-packages/telegram/request/_httpxrequest.py", line 292, in do_request
    raise NetworkError(f"httpx.{err.__class__.__name__}: {err}") from err
telegram.error.NetworkError: httpx.ReadError: 
Error while getting Updates: httpx.ReadError: 
No error handlers are registered, logging exception.
Traceback (most recent call last):
  File "/root/jupyter-env/lib/python3.12/site-packages/httpx/_transports/default.py", line 66, in map_httpcore_exceptions
    yield
  File "/root/jupyter-env/lib/python3.12/site-packages/httpx/_transports/default.py", line 366, in handle_async_request
    resp = await self._pool.handle_async_request(req)
           ^^^^^^^^^^^^^^^^^^^^^^^^^^^^^^^^^^^^^^^^^^
  File "/root/jupyter-env/lib/python3.12/site-packages/httpcore/_async/connection_pool.py", line 256, in handle_async_request
    raise exc from None
  File "/root/jupyter-env/lib/python3.12/site-packages/httpcore/_async/connection_pool.py", line 236, in handle_async_request
    response = await connection.handle_async_request(
               ^^^^^^^^^^^^^^^^^^^^^^^^^^^^^^^^^^^^^^
  File "/root/jupyter-env/lib/python3.12/site-packages/httpcore/_async/connection.py", line 103, in handle_async_request
    return await self._connection.handle_async_request(request)
           ^^^^^^^^^^^^^^^^^^^^^^^^^^^^^^^^^^^^^^^^^^^^^^^^^^^^
  File "/root/jupyter-env/lib/python3.12/site-packages/httpcore/_async/http11.py", line 136, in handle_async_request
    raise exc
  File "/root/jupyter-env/lib/python3.12/site-packages/httpcore/_async/http11.py", line 106, in handle_async_request
    ) = await self._receive_response_headers(**kwargs)
        ^^^^^^^^^^^^^^^^^^^^^^^^^^^^^^^^^^^^^^^^^^^^^^
  File "/root/jupyter-env/lib/python3.12/site-packages/httpcore/_async/http11.py", line 177, in _receive_response_headers
    event = await self._receive_event(timeout=timeout)
            ^^^^^^^^^^^^^^^^^^^^^^^^^^^^^^^^^^^^^^^^^^
  File "/root/jupyter-env/lib/python3.12/site-packages/httpcore/_async/http11.py", line 217, in _receive_event
    data = await self._network_stream.read(
           ^^^^^^^^^^^^^^^^^^^^^^^^^^^^^^^^
  File "/root/jupyter-env/lib/python3.12/site-packages/httpcore/_backends/anyio.py", line 32, in read
    with map_exceptions(exc_map):
  File "/usr/lib/python3.12/contextlib.py", line 158, in __exit__
    self.gen.throw(value)
  File "/root/jupyter-env/lib/python3.12/site-packages/httpcore/_exceptions.py", line 14, in map_exceptions
    raise to_exc(exc) from exc
httpcore.ReadError

The above exception was the direct cause of the following exception:

Traceback (most recent call last):
  File "/root/jupyter-env/lib/python3.12/site-packages/telegram/request/_httpxrequest.py", line 268, in do_request
    res = await self._client.request(
          ^^^^^^^^^^^^^^^^^^^^^^^^^^^
  File "/root/jupyter-env/lib/python3.12/site-packages/httpx/_client.py", line 1530, in request
    return await self.send(request, auth=auth, follow_redirects=follow_redirects)
           ^^^^^^^^^^^^^^^^^^^^^^^^^^^^^^^^^^^^^^^^^^^^^^^^^^^^^^^^^^^^^^^^^^^^^^
  File "/root/jupyter-env/lib/python3.12/site-packages/httpx/_client.py", line 1617, in send
    response = await self._send_handling_auth(
               ^^^^^^^^^^^^^^^^^^^^^^^^^^^^^^^
  File "/root/jupyter-env/lib/python3.12/site-packages/httpx/_client.py", line 1645, in _send_handling_auth
    response = await self._send_handling_redirects(
               ^^^^^^^^^^^^^^^^^^^^^^^^^^^^^^^^^^^^
  File "/root/jupyter-env/lib/python3.12/site-packages/httpx/_client.py", line 1682, in _send_handling_redirects
    response = await self._send_single_request(request)
               ^^^^^^^^^^^^^^^^^^^^^^^^^^^^^^^^^^^^^^^^
  File "/root/jupyter-env/lib/python3.12/site-packages/httpx/_client.py", line 1719, in _send_single_request
    response = await transport.handle_async_request(request)
               ^^^^^^^^^^^^^^^^^^^^^^^^^^^^^^^^^^^^^^^^^^^^^
  File "/root/jupyter-env/lib/python3.12/site-packages/httpx/_transports/default.py", line 365, in handle_async_request
    with map_httpcore_exceptions():
  File "/usr/lib/python3.12/contextlib.py", line 158, in __exit__
    self.gen.throw(value)
  File "/root/jupyter-env/lib/python3.12/site-packages/httpx/_transports/default.py", line 83, in map_httpcore_exceptions
    raise mapped_exc(message) from exc
httpx.ReadError

The above exception was the direct cause of the following exception:

Traceback (most recent call last):
  File "/root/jupyter-env/lib/python3.12/site-packages/telegram/ext/_updater.py", line 688, in _network_loop_retry
    if not await action_cb():
           ^^^^^^^^^^^^^^^^^
  File "/root/jupyter-env/lib/python3.12/site-packages/telegram/ext/_updater.py", line 384, in polling_action_cb
    raise exc
  File "/root/jupyter-env/lib/python3.12/site-packages/telegram/ext/_updater.py", line 373, in polling_action_cb
    updates = await self.bot.get_updates(
              ^^^^^^^^^^^^^^^^^^^^^^^^^^^
  File "/root/jupyter-env/lib/python3.12/site-packages/telegram/ext/_extbot.py", line 558, in get_updates
    updates = await super().get_updates(
              ^^^^^^^^^^^^^^^^^^^^^^^^^^
  File "/root/jupyter-env/lib/python3.12/site-packages/telegram/_bot.py", line 525, in decorator
    result = await func(self, *args, **kwargs)  # skipcq: PYL-E1102
             ^^^^^^^^^^^^^^^^^^^^^^^^^^^^^^^^^
  File "/root/jupyter-env/lib/python3.12/site-packages/telegram/_bot.py", line 3584, in get_updates
    await self._post(
  File "/root/jupyter-env/lib/python3.12/site-packages/telegram/_bot.py", line 613, in _post
    return await self._do_post(
           ^^^^^^^^^^^^^^^^^^^^
  File "/root/jupyter-env/lib/python3.12/site-packages/telegram/ext/_extbot.py", line 340, in _do_post
    return await super()._do_post(
           ^^^^^^^^^^^^^^^^^^^^^^^
  File "/root/jupyter-env/lib/python3.12/site-packages/telegram/_bot.py", line 641, in _do_post
    return await request.post(
           ^^^^^^^^^^^^^^^^^^^
  File "/root/jupyter-env/lib/python3.12/site-packages/telegram/request/_baserequest.py", line 200, in post
    result = await self._request_wrapper(
             ^^^^^^^^^^^^^^^^^^^^^^^^^^^^
  File "/root/jupyter-env/lib/python3.12/site-packages/telegram/request/_baserequest.py", line 340, in _request_wrapper
    raise exc
  File "/root/jupyter-env/lib/python3.12/site-packages/telegram/request/_baserequest.py", line 330, in _request_wrapper
    code, payload = await self.do_request(
                    ^^^^^^^^^^^^^^^^^^^^^^
  File "/root/jupyter-env/lib/python3.12/site-packages/telegram/request/_httpxrequest.py", line 292, in do_request
    raise NetworkError(f"httpx.{err.__class__.__name__}: {err}") from err
telegram.error.NetworkError: httpx.ReadError: 
Error while getting Updates: httpx.ReadError: 
No error handlers are registered, logging exception.
Traceback (most recent call last):
  File "/root/jupyter-env/lib/python3.12/site-packages/httpx/_transports/default.py", line 66, in map_httpcore_exceptions
    yield
  File "/root/jupyter-env/lib/python3.12/site-packages/httpx/_transports/default.py", line 366, in handle_async_request
    resp = await self._pool.handle_async_request(req)
           ^^^^^^^^^^^^^^^^^^^^^^^^^^^^^^^^^^^^^^^^^^
  File "/root/jupyter-env/lib/python3.12/site-packages/httpcore/_async/connection_pool.py", line 256, in handle_async_request
    raise exc from None
  File "/root/jupyter-env/lib/python3.12/site-packages/httpcore/_async/connection_pool.py", line 236, in handle_async_request
    response = await connection.handle_async_request(
               ^^^^^^^^^^^^^^^^^^^^^^^^^^^^^^^^^^^^^^
  File "/root/jupyter-env/lib/python3.12/site-packages/httpcore/_async/connection.py", line 103, in handle_async_request
    return await self._connection.handle_async_request(request)
           ^^^^^^^^^^^^^^^^^^^^^^^^^^^^^^^^^^^^^^^^^^^^^^^^^^^^
  File "/root/jupyter-env/lib/python3.12/site-packages/httpcore/_async/http11.py", line 136, in handle_async_request
    raise exc
  File "/root/jupyter-env/lib/python3.12/site-packages/httpcore/_async/http11.py", line 106, in handle_async_request
    ) = await self._receive_response_headers(**kwargs)
        ^^^^^^^^^^^^^^^^^^^^^^^^^^^^^^^^^^^^^^^^^^^^^^
  File "/root/jupyter-env/lib/python3.12/site-packages/httpcore/_async/http11.py", line 177, in _receive_response_headers
    event = await self._receive_event(timeout=timeout)
            ^^^^^^^^^^^^^^^^^^^^^^^^^^^^^^^^^^^^^^^^^^
  File "/root/jupyter-env/lib/python3.12/site-packages/httpcore/_async/http11.py", line 217, in _receive_event
    data = await self._network_stream.read(
           ^^^^^^^^^^^^^^^^^^^^^^^^^^^^^^^^
  File "/root/jupyter-env/lib/python3.12/site-packages/httpcore/_backends/anyio.py", line 32, in read
    with map_exceptions(exc_map):
  File "/usr/lib/python3.12/contextlib.py", line 158, in __exit__
    self.gen.throw(value)
  File "/root/jupyter-env/lib/python3.12/site-packages/httpcore/_exceptions.py", line 14, in map_exceptions
    raise to_exc(exc) from exc
httpcore.ReadError

The above exception was the direct cause of the following exception:

Traceback (most recent call last):
  File "/root/jupyter-env/lib/python3.12/site-packages/telegram/request/_httpxrequest.py", line 268, in do_request
    res = await self._client.request(
          ^^^^^^^^^^^^^^^^^^^^^^^^^^^
  File "/root/jupyter-env/lib/python3.12/site-packages/httpx/_client.py", line 1530, in request
    return await self.send(request, auth=auth, follow_redirects=follow_redirects)
           ^^^^^^^^^^^^^^^^^^^^^^^^^^^^^^^^^^^^^^^^^^^^^^^^^^^^^^^^^^^^^^^^^^^^^^
  File "/root/jupyter-env/lib/python3.12/site-packages/httpx/_client.py", line 1617, in send
    response = await self._send_handling_auth(
               ^^^^^^^^^^^^^^^^^^^^^^^^^^^^^^^
  File "/root/jupyter-env/lib/python3.12/site-packages/httpx/_client.py", line 1645, in _send_handling_auth
    response = await self._send_handling_redirects(
               ^^^^^^^^^^^^^^^^^^^^^^^^^^^^^^^^^^^^
  File "/root/jupyter-env/lib/python3.12/site-packages/httpx/_client.py", line 1682, in _send_handling_redirects
    response = await self._send_single_request(request)
               ^^^^^^^^^^^^^^^^^^^^^^^^^^^^^^^^^^^^^^^^
  File "/root/jupyter-env/lib/python3.12/site-packages/httpx/_client.py", line 1719, in _send_single_request
    response = await transport.handle_async_request(request)
               ^^^^^^^^^^^^^^^^^^^^^^^^^^^^^^^^^^^^^^^^^^^^^
  File "/root/jupyter-env/lib/python3.12/site-packages/httpx/_transports/default.py", line 365, in handle_async_request
    with map_httpcore_exceptions():
  File "/usr/lib/python3.12/contextlib.py", line 158, in __exit__
    self.gen.throw(value)
  File "/root/jupyter-env/lib/python3.12/site-packages/httpx/_transports/default.py", line 83, in map_httpcore_exceptions
    raise mapped_exc(message) from exc
httpx.ReadError

The above exception was the direct cause of the following exception:

Traceback (most recent call last):
  File "/root/jupyter-env/lib/python3.12/site-packages/telegram/ext/_updater.py", line 688, in _network_loop_retry
    if not await action_cb():
           ^^^^^^^^^^^^^^^^^
  File "/root/jupyter-env/lib/python3.12/site-packages/telegram/ext/_updater.py", line 384, in polling_action_cb
    raise exc
  File "/root/jupyter-env/lib/python3.12/site-packages/telegram/ext/_updater.py", line 373, in polling_action_cb
    updates = await self.bot.get_updates(
              ^^^^^^^^^^^^^^^^^^^^^^^^^^^
  File "/root/jupyter-env/lib/python3.12/site-packages/telegram/ext/_extbot.py", line 558, in get_updates
    updates = await super().get_updates(
              ^^^^^^^^^^^^^^^^^^^^^^^^^^
  File "/root/jupyter-env/lib/python3.12/site-packages/telegram/_bot.py", line 525, in decorator
    result = await func(self, *args, **kwargs)  # skipcq: PYL-E1102
             ^^^^^^^^^^^^^^^^^^^^^^^^^^^^^^^^^
  File "/root/jupyter-env/lib/python3.12/site-packages/telegram/_bot.py", line 3584, in get_updates
    await self._post(
  File "/root/jupyter-env/lib/python3.12/site-packages/telegram/_bot.py", line 613, in _post
    return await self._do_post(
           ^^^^^^^^^^^^^^^^^^^^
  File "/root/jupyter-env/lib/python3.12/site-packages/telegram/ext/_extbot.py", line 340, in _do_post
    return await super()._do_post(
           ^^^^^^^^^^^^^^^^^^^^^^^
  File "/root/jupyter-env/lib/python3.12/site-packages/telegram/_bot.py", line 641, in _do_post
    return await request.post(
           ^^^^^^^^^^^^^^^^^^^
  File "/root/jupyter-env/lib/python3.12/site-packages/telegram/request/_baserequest.py", line 200, in post
    result = await self._request_wrapper(
             ^^^^^^^^^^^^^^^^^^^^^^^^^^^^
  File "/root/jupyter-env/lib/python3.12/site-packages/telegram/request/_baserequest.py", line 340, in _request_wrapper
    raise exc
  File "/root/jupyter-env/lib/python3.12/site-packages/telegram/request/_baserequest.py", line 330, in _request_wrapper
    code, payload = await self.do_request(
                    ^^^^^^^^^^^^^^^^^^^^^^
  File "/root/jupyter-env/lib/python3.12/site-packages/telegram/request/_httpxrequest.py", line 292, in do_request
    raise NetworkError(f"httpx.{err.__class__.__name__}: {err}") from err
telegram.error.NetworkError: httpx.ReadError: 
Error while getting Updates: httpx.ReadError: 
No error handlers are registered, logging exception.
Traceback (most recent call last):
  File "/root/jupyter-env/lib/python3.12/site-packages/httpx/_transports/default.py", line 66, in map_httpcore_exceptions
    yield
  File "/root/jupyter-env/lib/python3.12/site-packages/httpx/_transports/default.py", line 366, in handle_async_request
    resp = await self._pool.handle_async_request(req)
           ^^^^^^^^^^^^^^^^^^^^^^^^^^^^^^^^^^^^^^^^^^
  File "/root/jupyter-env/lib/python3.12/site-packages/httpcore/_async/connection_pool.py", line 256, in handle_async_request
    raise exc from None
  File "/root/jupyter-env/lib/python3.12/site-packages/httpcore/_async/connection_pool.py", line 236, in handle_async_request
    response = await connection.handle_async_request(
               ^^^^^^^^^^^^^^^^^^^^^^^^^^^^^^^^^^^^^^
  File "/root/jupyter-env/lib/python3.12/site-packages/httpcore/_async/connection.py", line 103, in handle_async_request
    return await self._connection.handle_async_request(request)
           ^^^^^^^^^^^^^^^^^^^^^^^^^^^^^^^^^^^^^^^^^^^^^^^^^^^^
  File "/root/jupyter-env/lib/python3.12/site-packages/httpcore/_async/http11.py", line 136, in handle_async_request
    raise exc
  File "/root/jupyter-env/lib/python3.12/site-packages/httpcore/_async/http11.py", line 106, in handle_async_request
    ) = await self._receive_response_headers(**kwargs)
        ^^^^^^^^^^^^^^^^^^^^^^^^^^^^^^^^^^^^^^^^^^^^^^
  File "/root/jupyter-env/lib/python3.12/site-packages/httpcore/_async/http11.py", line 177, in _receive_response_headers
    event = await self._receive_event(timeout=timeout)
            ^^^^^^^^^^^^^^^^^^^^^^^^^^^^^^^^^^^^^^^^^^
  File "/root/jupyter-env/lib/python3.12/site-packages/httpcore/_async/http11.py", line 217, in _receive_event
    data = await self._network_stream.read(
           ^^^^^^^^^^^^^^^^^^^^^^^^^^^^^^^^
  File "/root/jupyter-env/lib/python3.12/site-packages/httpcore/_backends/anyio.py", line 32, in read
    with map_exceptions(exc_map):
  File "/usr/lib/python3.12/contextlib.py", line 158, in __exit__
    self.gen.throw(value)
  File "/root/jupyter-env/lib/python3.12/site-packages/httpcore/_exceptions.py", line 14, in map_exceptions
    raise to_exc(exc) from exc
httpcore.ReadError

The above exception was the direct cause of the following exception:

Traceback (most recent call last):
  File "/root/jupyter-env/lib/python3.12/site-packages/telegram/request/_httpxrequest.py", line 268, in do_request
    res = await self._client.request(
          ^^^^^^^^^^^^^^^^^^^^^^^^^^^
  File "/root/jupyter-env/lib/python3.12/site-packages/httpx/_client.py", line 1530, in request
    return await self.send(request, auth=auth, follow_redirects=follow_redirects)
           ^^^^^^^^^^^^^^^^^^^^^^^^^^^^^^^^^^^^^^^^^^^^^^^^^^^^^^^^^^^^^^^^^^^^^^
  File "/root/jupyter-env/lib/python3.12/site-packages/httpx/_client.py", line 1617, in send
    response = await self._send_handling_auth(
               ^^^^^^^^^^^^^^^^^^^^^^^^^^^^^^^
  File "/root/jupyter-env/lib/python3.12/site-packages/httpx/_client.py", line 1645, in _send_handling_auth
    response = await self._send_handling_redirects(
               ^^^^^^^^^^^^^^^^^^^^^^^^^^^^^^^^^^^^
  File "/root/jupyter-env/lib/python3.12/site-packages/httpx/_client.py", line 1682, in _send_handling_redirects
    response = await self._send_single_request(request)
               ^^^^^^^^^^^^^^^^^^^^^^^^^^^^^^^^^^^^^^^^
  File "/root/jupyter-env/lib/python3.12/site-packages/httpx/_client.py", line 1719, in _send_single_request
    response = await transport.handle_async_request(request)
               ^^^^^^^^^^^^^^^^^^^^^^^^^^^^^^^^^^^^^^^^^^^^^
  File "/root/jupyter-env/lib/python3.12/site-packages/httpx/_transports/default.py", line 365, in handle_async_request
    with map_httpcore_exceptions():
  File "/usr/lib/python3.12/contextlib.py", line 158, in __exit__
    self.gen.throw(value)
  File "/root/jupyter-env/lib/python3.12/site-packages/httpx/_transports/default.py", line 83, in map_httpcore_exceptions
    raise mapped_exc(message) from exc
httpx.ReadError

The above exception was the direct cause of the following exception:

Traceback (most recent call last):
  File "/root/jupyter-env/lib/python3.12/site-packages/telegram/ext/_updater.py", line 688, in _network_loop_retry
    if not await action_cb():
           ^^^^^^^^^^^^^^^^^
  File "/root/jupyter-env/lib/python3.12/site-packages/telegram/ext/_updater.py", line 384, in polling_action_cb
    raise exc
  File "/root/jupyter-env/lib/python3.12/site-packages/telegram/ext/_updater.py", line 373, in polling_action_cb
    updates = await self.bot.get_updates(
              ^^^^^^^^^^^^^^^^^^^^^^^^^^^
  File "/root/jupyter-env/lib/python3.12/site-packages/telegram/ext/_extbot.py", line 558, in get_updates
    updates = await super().get_updates(
              ^^^^^^^^^^^^^^^^^^^^^^^^^^
  File "/root/jupyter-env/lib/python3.12/site-packages/telegram/_bot.py", line 525, in decorator
    result = await func(self, *args, **kwargs)  # skipcq: PYL-E1102
             ^^^^^^^^^^^^^^^^^^^^^^^^^^^^^^^^^
  File "/root/jupyter-env/lib/python3.12/site-packages/telegram/_bot.py", line 3584, in get_updates
    await self._post(
  File "/root/jupyter-env/lib/python3.12/site-packages/telegram/_bot.py", line 613, in _post
    return await self._do_post(
           ^^^^^^^^^^^^^^^^^^^^
  File "/root/jupyter-env/lib/python3.12/site-packages/telegram/ext/_extbot.py", line 340, in _do_post
    return await super()._do_post(
           ^^^^^^^^^^^^^^^^^^^^^^^
  File "/root/jupyter-env/lib/python3.12/site-packages/telegram/_bot.py", line 641, in _do_post
    return await request.post(
           ^^^^^^^^^^^^^^^^^^^
  File "/root/jupyter-env/lib/python3.12/site-packages/telegram/request/_baserequest.py", line 200, in post
    result = await self._request_wrapper(
             ^^^^^^^^^^^^^^^^^^^^^^^^^^^^
  File "/root/jupyter-env/lib/python3.12/site-packages/telegram/request/_baserequest.py", line 340, in _request_wrapper
    raise exc
  File "/root/jupyter-env/lib/python3.12/site-packages/telegram/request/_baserequest.py", line 330, in _request_wrapper
    code, payload = await self.do_request(
                    ^^^^^^^^^^^^^^^^^^^^^^
  File "/root/jupyter-env/lib/python3.12/site-packages/telegram/request/_httpxrequest.py", line 292, in do_request
    raise NetworkError(f"httpx.{err.__class__.__name__}: {err}") from err
telegram.error.NetworkError: httpx.ReadError: 
Error while getting Updates: httpx.ReadError: 
No error handlers are registered, logging exception.
Traceback (most recent call last):
  File "/root/jupyter-env/lib/python3.12/site-packages/httpx/_transports/default.py", line 66, in map_httpcore_exceptions
    yield
  File "/root/jupyter-env/lib/python3.12/site-packages/httpx/_transports/default.py", line 366, in handle_async_request
    resp = await self._pool.handle_async_request(req)
           ^^^^^^^^^^^^^^^^^^^^^^^^^^^^^^^^^^^^^^^^^^
  File "/root/jupyter-env/lib/python3.12/site-packages/httpcore/_async/connection_pool.py", line 256, in handle_async_request
    raise exc from None
  File "/root/jupyter-env/lib/python3.12/site-packages/httpcore/_async/connection_pool.py", line 236, in handle_async_request
    response = await connection.handle_async_request(
               ^^^^^^^^^^^^^^^^^^^^^^^^^^^^^^^^^^^^^^
  File "/root/jupyter-env/lib/python3.12/site-packages/httpcore/_async/connection.py", line 103, in handle_async_request
    return await self._connection.handle_async_request(request)
           ^^^^^^^^^^^^^^^^^^^^^^^^^^^^^^^^^^^^^^^^^^^^^^^^^^^^
  File "/root/jupyter-env/lib/python3.12/site-packages/httpcore/_async/http11.py", line 136, in handle_async_request
    raise exc
  File "/root/jupyter-env/lib/python3.12/site-packages/httpcore/_async/http11.py", line 106, in handle_async_request
    ) = await self._receive_response_headers(**kwargs)
        ^^^^^^^^^^^^^^^^^^^^^^^^^^^^^^^^^^^^^^^^^^^^^^
  File "/root/jupyter-env/lib/python3.12/site-packages/httpcore/_async/http11.py", line 177, in _receive_response_headers
    event = await self._receive_event(timeout=timeout)
            ^^^^^^^^^^^^^^^^^^^^^^^^^^^^^^^^^^^^^^^^^^
  File "/root/jupyter-env/lib/python3.12/site-packages/httpcore/_async/http11.py", line 217, in _receive_event
    data = await self._network_stream.read(
           ^^^^^^^^^^^^^^^^^^^^^^^^^^^^^^^^
  File "/root/jupyter-env/lib/python3.12/site-packages/httpcore/_backends/anyio.py", line 32, in read
    with map_exceptions(exc_map):
  File "/usr/lib/python3.12/contextlib.py", line 158, in __exit__
    self.gen.throw(value)
  File "/root/jupyter-env/lib/python3.12/site-packages/httpcore/_exceptions.py", line 14, in map_exceptions
    raise to_exc(exc) from exc
httpcore.ReadError

The above exception was the direct cause of the following exception:

Traceback (most recent call last):
  File "/root/jupyter-env/lib/python3.12/site-packages/telegram/request/_httpxrequest.py", line 268, in do_request
    res = await self._client.request(
          ^^^^^^^^^^^^^^^^^^^^^^^^^^^
  File "/root/jupyter-env/lib/python3.12/site-packages/httpx/_client.py", line 1530, in request
    return await self.send(request, auth=auth, follow_redirects=follow_redirects)
           ^^^^^^^^^^^^^^^^^^^^^^^^^^^^^^^^^^^^^^^^^^^^^^^^^^^^^^^^^^^^^^^^^^^^^^
  File "/root/jupyter-env/lib/python3.12/site-packages/httpx/_client.py", line 1617, in send
    response = await self._send_handling_auth(
               ^^^^^^^^^^^^^^^^^^^^^^^^^^^^^^^
  File "/root/jupyter-env/lib/python3.12/site-packages/httpx/_client.py", line 1645, in _send_handling_auth
    response = await self._send_handling_redirects(
               ^^^^^^^^^^^^^^^^^^^^^^^^^^^^^^^^^^^^
  File "/root/jupyter-env/lib/python3.12/site-packages/httpx/_client.py", line 1682, in _send_handling_redirects
    response = await self._send_single_request(request)
               ^^^^^^^^^^^^^^^^^^^^^^^^^^^^^^^^^^^^^^^^
  File "/root/jupyter-env/lib/python3.12/site-packages/httpx/_client.py", line 1719, in _send_single_request
    response = await transport.handle_async_request(request)
               ^^^^^^^^^^^^^^^^^^^^^^^^^^^^^^^^^^^^^^^^^^^^^
  File "/root/jupyter-env/lib/python3.12/site-packages/httpx/_transports/default.py", line 365, in handle_async_request
    with map_httpcore_exceptions():
  File "/usr/lib/python3.12/contextlib.py", line 158, in __exit__
    self.gen.throw(value)
  File "/root/jupyter-env/lib/python3.12/site-packages/httpx/_transports/default.py", line 83, in map_httpcore_exceptions
    raise mapped_exc(message) from exc
httpx.ReadError

The above exception was the direct cause of the following exception:

Traceback (most recent call last):
  File "/root/jupyter-env/lib/python3.12/site-packages/telegram/ext/_updater.py", line 688, in _network_loop_retry
    if not await action_cb():
           ^^^^^^^^^^^^^^^^^
  File "/root/jupyter-env/lib/python3.12/site-packages/telegram/ext/_updater.py", line 384, in polling_action_cb
    raise exc
  File "/root/jupyter-env/lib/python3.12/site-packages/telegram/ext/_updater.py", line 373, in polling_action_cb
    updates = await self.bot.get_updates(
              ^^^^^^^^^^^^^^^^^^^^^^^^^^^
  File "/root/jupyter-env/lib/python3.12/site-packages/telegram/ext/_extbot.py", line 558, in get_updates
    updates = await super().get_updates(
              ^^^^^^^^^^^^^^^^^^^^^^^^^^
  File "/root/jupyter-env/lib/python3.12/site-packages/telegram/_bot.py", line 525, in decorator
    result = await func(self, *args, **kwargs)  # skipcq: PYL-E1102
             ^^^^^^^^^^^^^^^^^^^^^^^^^^^^^^^^^
  File "/root/jupyter-env/lib/python3.12/site-packages/telegram/_bot.py", line 3584, in get_updates
    await self._post(
  File "/root/jupyter-env/lib/python3.12/site-packages/telegram/_bot.py", line 613, in _post
    return await self._do_post(
           ^^^^^^^^^^^^^^^^^^^^
  File "/root/jupyter-env/lib/python3.12/site-packages/telegram/ext/_extbot.py", line 340, in _do_post
    return await super()._do_post(
           ^^^^^^^^^^^^^^^^^^^^^^^
  File "/root/jupyter-env/lib/python3.12/site-packages/telegram/_bot.py", line 641, in _do_post
    return await request.post(
           ^^^^^^^^^^^^^^^^^^^
  File "/root/jupyter-env/lib/python3.12/site-packages/telegram/request/_baserequest.py", line 200, in post
    result = await self._request_wrapper(
             ^^^^^^^^^^^^^^^^^^^^^^^^^^^^
  File "/root/jupyter-env/lib/python3.12/site-packages/telegram/request/_baserequest.py", line 340, in _request_wrapper
    raise exc
  File "/root/jupyter-env/lib/python3.12/site-packages/telegram/request/_baserequest.py", line 330, in _request_wrapper
    code, payload = await self.do_request(
                    ^^^^^^^^^^^^^^^^^^^^^^
  File "/root/jupyter-env/lib/python3.12/site-packages/telegram/request/_httpxrequest.py", line 292, in do_request
    raise NetworkError(f"httpx.{err.__class__.__name__}: {err}") from err
telegram.error.NetworkError: httpx.ReadError: 
Error while getting Updates: httpx.ReadError: 
No error handlers are registered, logging exception.
Traceback (most recent call last):
  File "/root/jupyter-env/lib/python3.12/site-packages/httpx/_transports/default.py", line 66, in map_httpcore_exceptions
    yield
  File "/root/jupyter-env/lib/python3.12/site-packages/httpx/_transports/default.py", line 366, in handle_async_request
    resp = await self._pool.handle_async_request(req)
           ^^^^^^^^^^^^^^^^^^^^^^^^^^^^^^^^^^^^^^^^^^
  File "/root/jupyter-env/lib/python3.12/site-packages/httpcore/_async/connection_pool.py", line 256, in handle_async_request
    raise exc from None
  File "/root/jupyter-env/lib/python3.12/site-packages/httpcore/_async/connection_pool.py", line 236, in handle_async_request
    response = await connection.handle_async_request(
               ^^^^^^^^^^^^^^^^^^^^^^^^^^^^^^^^^^^^^^
  File "/root/jupyter-env/lib/python3.12/site-packages/httpcore/_async/connection.py", line 103, in handle_async_request
    return await self._connection.handle_async_request(request)
           ^^^^^^^^^^^^^^^^^^^^^^^^^^^^^^^^^^^^^^^^^^^^^^^^^^^^
  File "/root/jupyter-env/lib/python3.12/site-packages/httpcore/_async/http11.py", line 136, in handle_async_request
    raise exc
  File "/root/jupyter-env/lib/python3.12/site-packages/httpcore/_async/http11.py", line 106, in handle_async_request
    ) = await self._receive_response_headers(**kwargs)
        ^^^^^^^^^^^^^^^^^^^^^^^^^^^^^^^^^^^^^^^^^^^^^^
  File "/root/jupyter-env/lib/python3.12/site-packages/httpcore/_async/http11.py", line 177, in _receive_response_headers
    event = await self._receive_event(timeout=timeout)
            ^^^^^^^^^^^^^^^^^^^^^^^^^^^^^^^^^^^^^^^^^^
  File "/root/jupyter-env/lib/python3.12/site-packages/httpcore/_async/http11.py", line 217, in _receive_event
    data = await self._network_stream.read(
           ^^^^^^^^^^^^^^^^^^^^^^^^^^^^^^^^
  File "/root/jupyter-env/lib/python3.12/site-packages/httpcore/_backends/anyio.py", line 32, in read
    with map_exceptions(exc_map):
  File "/usr/lib/python3.12/contextlib.py", line 158, in __exit__
    self.gen.throw(value)
  File "/root/jupyter-env/lib/python3.12/site-packages/httpcore/_exceptions.py", line 14, in map_exceptions
    raise to_exc(exc) from exc
httpcore.ReadError

The above exception was the direct cause of the following exception:

Traceback (most recent call last):
  File "/root/jupyter-env/lib/python3.12/site-packages/telegram/request/_httpxrequest.py", line 268, in do_request
    res = await self._client.request(
          ^^^^^^^^^^^^^^^^^^^^^^^^^^^
  File "/root/jupyter-env/lib/python3.12/site-packages/httpx/_client.py", line 1530, in request
    return await self.send(request, auth=auth, follow_redirects=follow_redirects)
           ^^^^^^^^^^^^^^^^^^^^^^^^^^^^^^^^^^^^^^^^^^^^^^^^^^^^^^^^^^^^^^^^^^^^^^
  File "/root/jupyter-env/lib/python3.12/site-packages/httpx/_client.py", line 1617, in send
    response = await self._send_handling_auth(
               ^^^^^^^^^^^^^^^^^^^^^^^^^^^^^^^
  File "/root/jupyter-env/lib/python3.12/site-packages/httpx/_client.py", line 1645, in _send_handling_auth
    response = await self._send_handling_redirects(
               ^^^^^^^^^^^^^^^^^^^^^^^^^^^^^^^^^^^^
  File "/root/jupyter-env/lib/python3.12/site-packages/httpx/_client.py", line 1682, in _send_handling_redirects
    response = await self._send_single_request(request)
               ^^^^^^^^^^^^^^^^^^^^^^^^^^^^^^^^^^^^^^^^
  File "/root/jupyter-env/lib/python3.12/site-packages/httpx/_client.py", line 1719, in _send_single_request
    response = await transport.handle_async_request(request)
               ^^^^^^^^^^^^^^^^^^^^^^^^^^^^^^^^^^^^^^^^^^^^^
  File "/root/jupyter-env/lib/python3.12/site-packages/httpx/_transports/default.py", line 365, in handle_async_request
    with map_httpcore_exceptions():
  File "/usr/lib/python3.12/contextlib.py", line 158, in __exit__
    self.gen.throw(value)
  File "/root/jupyter-env/lib/python3.12/site-packages/httpx/_transports/default.py", line 83, in map_httpcore_exceptions
    raise mapped_exc(message) from exc
httpx.ReadError

The above exception was the direct cause of the following exception:

Traceback (most recent call last):
  File "/root/jupyter-env/lib/python3.12/site-packages/telegram/ext/_updater.py", line 688, in _network_loop_retry
    if not await action_cb():
           ^^^^^^^^^^^^^^^^^
  File "/root/jupyter-env/lib/python3.12/site-packages/telegram/ext/_updater.py", line 384, in polling_action_cb
    raise exc
  File "/root/jupyter-env/lib/python3.12/site-packages/telegram/ext/_updater.py", line 373, in polling_action_cb
    updates = await self.bot.get_updates(
              ^^^^^^^^^^^^^^^^^^^^^^^^^^^
  File "/root/jupyter-env/lib/python3.12/site-packages/telegram/ext/_extbot.py", line 558, in get_updates
    updates = await super().get_updates(
              ^^^^^^^^^^^^^^^^^^^^^^^^^^
  File "/root/jupyter-env/lib/python3.12/site-packages/telegram/_bot.py", line 525, in decorator
    result = await func(self, *args, **kwargs)  # skipcq: PYL-E1102
             ^^^^^^^^^^^^^^^^^^^^^^^^^^^^^^^^^
  File "/root/jupyter-env/lib/python3.12/site-packages/telegram/_bot.py", line 3584, in get_updates
    await self._post(
  File "/root/jupyter-env/lib/python3.12/site-packages/telegram/_bot.py", line 613, in _post
    return await self._do_post(
           ^^^^^^^^^^^^^^^^^^^^
  File "/root/jupyter-env/lib/python3.12/site-packages/telegram/ext/_extbot.py", line 340, in _do_post
    return await super()._do_post(
           ^^^^^^^^^^^^^^^^^^^^^^^
  File "/root/jupyter-env/lib/python3.12/site-packages/telegram/_bot.py", line 641, in _do_post
    return await request.post(
           ^^^^^^^^^^^^^^^^^^^
  File "/root/jupyter-env/lib/python3.12/site-packages/telegram/request/_baserequest.py", line 200, in post
    result = await self._request_wrapper(
             ^^^^^^^^^^^^^^^^^^^^^^^^^^^^
  File "/root/jupyter-env/lib/python3.12/site-packages/telegram/request/_baserequest.py", line 340, in _request_wrapper
    raise exc
  File "/root/jupyter-env/lib/python3.12/site-packages/telegram/request/_baserequest.py", line 330, in _request_wrapper
    code, payload = await self.do_request(
                    ^^^^^^^^^^^^^^^^^^^^^^
  File "/root/jupyter-env/lib/python3.12/site-packages/telegram/request/_httpxrequest.py", line 292, in do_request
    raise NetworkError(f"httpx.{err.__class__.__name__}: {err}") from err
telegram.error.NetworkError: httpx.ReadError: 
Error while getting Updates: httpx.ReadError: 
No error handlers are registered, logging exception.
Traceback (most recent call last):
  File "/root/jupyter-env/lib/python3.12/site-packages/httpx/_transports/default.py", line 66, in map_httpcore_exceptions
    yield
  File "/root/jupyter-env/lib/python3.12/site-packages/httpx/_transports/default.py", line 366, in handle_async_request
    resp = await self._pool.handle_async_request(req)
           ^^^^^^^^^^^^^^^^^^^^^^^^^^^^^^^^^^^^^^^^^^
  File "/root/jupyter-env/lib/python3.12/site-packages/httpcore/_async/connection_pool.py", line 256, in handle_async_request
    raise exc from None
  File "/root/jupyter-env/lib/python3.12/site-packages/httpcore/_async/connection_pool.py", line 236, in handle_async_request
    response = await connection.handle_async_request(
               ^^^^^^^^^^^^^^^^^^^^^^^^^^^^^^^^^^^^^^
  File "/root/jupyter-env/lib/python3.12/site-packages/httpcore/_async/connection.py", line 103, in handle_async_request
    return await self._connection.handle_async_request(request)
           ^^^^^^^^^^^^^^^^^^^^^^^^^^^^^^^^^^^^^^^^^^^^^^^^^^^^
  File "/root/jupyter-env/lib/python3.12/site-packages/httpcore/_async/http11.py", line 136, in handle_async_request
    raise exc
  File "/root/jupyter-env/lib/python3.12/site-packages/httpcore/_async/http11.py", line 106, in handle_async_request
    ) = await self._receive_response_headers(**kwargs)
        ^^^^^^^^^^^^^^^^^^^^^^^^^^^^^^^^^^^^^^^^^^^^^^
  File "/root/jupyter-env/lib/python3.12/site-packages/httpcore/_async/http11.py", line 177, in _receive_response_headers
    event = await self._receive_event(timeout=timeout)
            ^^^^^^^^^^^^^^^^^^^^^^^^^^^^^^^^^^^^^^^^^^
  File "/root/jupyter-env/lib/python3.12/site-packages/httpcore/_async/http11.py", line 217, in _receive_event
    data = await self._network_stream.read(
           ^^^^^^^^^^^^^^^^^^^^^^^^^^^^^^^^
  File "/root/jupyter-env/lib/python3.12/site-packages/httpcore/_backends/anyio.py", line 32, in read
    with map_exceptions(exc_map):
  File "/usr/lib/python3.12/contextlib.py", line 158, in __exit__
    self.gen.throw(value)
  File "/root/jupyter-env/lib/python3.12/site-packages/httpcore/_exceptions.py", line 14, in map_exceptions
    raise to_exc(exc) from exc
httpcore.ReadError

The above exception was the direct cause of the following exception:

Traceback (most recent call last):
  File "/root/jupyter-env/lib/python3.12/site-packages/telegram/request/_httpxrequest.py", line 268, in do_request
    res = await self._client.request(
          ^^^^^^^^^^^^^^^^^^^^^^^^^^^
  File "/root/jupyter-env/lib/python3.12/site-packages/httpx/_client.py", line 1530, in request
    return await self.send(request, auth=auth, follow_redirects=follow_redirects)
           ^^^^^^^^^^^^^^^^^^^^^^^^^^^^^^^^^^^^^^^^^^^^^^^^^^^^^^^^^^^^^^^^^^^^^^
  File "/root/jupyter-env/lib/python3.12/site-packages/httpx/_client.py", line 1617, in send
    response = await self._send_handling_auth(
               ^^^^^^^^^^^^^^^^^^^^^^^^^^^^^^^
  File "/root/jupyter-env/lib/python3.12/site-packages/httpx/_client.py", line 1645, in _send_handling_auth
    response = await self._send_handling_redirects(
               ^^^^^^^^^^^^^^^^^^^^^^^^^^^^^^^^^^^^
  File "/root/jupyter-env/lib/python3.12/site-packages/httpx/_client.py", line 1682, in _send_handling_redirects
    response = await self._send_single_request(request)
               ^^^^^^^^^^^^^^^^^^^^^^^^^^^^^^^^^^^^^^^^
  File "/root/jupyter-env/lib/python3.12/site-packages/httpx/_client.py", line 1719, in _send_single_request
    response = await transport.handle_async_request(request)
               ^^^^^^^^^^^^^^^^^^^^^^^^^^^^^^^^^^^^^^^^^^^^^
  File "/root/jupyter-env/lib/python3.12/site-packages/httpx/_transports/default.py", line 365, in handle_async_request
    with map_httpcore_exceptions():
  File "/usr/lib/python3.12/contextlib.py", line 158, in __exit__
    self.gen.throw(value)
  File "/root/jupyter-env/lib/python3.12/site-packages/httpx/_transports/default.py", line 83, in map_httpcore_exceptions
    raise mapped_exc(message) from exc
httpx.ReadError

The above exception was the direct cause of the following exception:

Traceback (most recent call last):
  File "/root/jupyter-env/lib/python3.12/site-packages/telegram/ext/_updater.py", line 688, in _network_loop_retry
    if not await action_cb():
           ^^^^^^^^^^^^^^^^^
  File "/root/jupyter-env/lib/python3.12/site-packages/telegram/ext/_updater.py", line 384, in polling_action_cb
    raise exc
  File "/root/jupyter-env/lib/python3.12/site-packages/telegram/ext/_updater.py", line 373, in polling_action_cb
    updates = await self.bot.get_updates(
              ^^^^^^^^^^^^^^^^^^^^^^^^^^^
  File "/root/jupyter-env/lib/python3.12/site-packages/telegram/ext/_extbot.py", line 558, in get_updates
    updates = await super().get_updates(
              ^^^^^^^^^^^^^^^^^^^^^^^^^^
  File "/root/jupyter-env/lib/python3.12/site-packages/telegram/_bot.py", line 525, in decorator
    result = await func(self, *args, **kwargs)  # skipcq: PYL-E1102
             ^^^^^^^^^^^^^^^^^^^^^^^^^^^^^^^^^
  File "/root/jupyter-env/lib/python3.12/site-packages/telegram/_bot.py", line 3584, in get_updates
    await self._post(
  File "/root/jupyter-env/lib/python3.12/site-packages/telegram/_bot.py", line 613, in _post
    return await self._do_post(
           ^^^^^^^^^^^^^^^^^^^^
  File "/root/jupyter-env/lib/python3.12/site-packages/telegram/ext/_extbot.py", line 340, in _do_post
    return await super()._do_post(
           ^^^^^^^^^^^^^^^^^^^^^^^
  File "/root/jupyter-env/lib/python3.12/site-packages/telegram/_bot.py", line 641, in _do_post
    return await request.post(
           ^^^^^^^^^^^^^^^^^^^
  File "/root/jupyter-env/lib/python3.12/site-packages/telegram/request/_baserequest.py", line 200, in post
    result = await self._request_wrapper(
             ^^^^^^^^^^^^^^^^^^^^^^^^^^^^
  File "/root/jupyter-env/lib/python3.12/site-packages/telegram/request/_baserequest.py", line 340, in _request_wrapper
    raise exc
  File "/root/jupyter-env/lib/python3.12/site-packages/telegram/request/_baserequest.py", line 330, in _request_wrapper
    code, payload = await self.do_request(
                    ^^^^^^^^^^^^^^^^^^^^^^
  File "/root/jupyter-env/lib/python3.12/site-packages/telegram/request/_httpxrequest.py", line 292, in do_request
    raise NetworkError(f"httpx.{err.__class__.__name__}: {err}") from err
telegram.error.NetworkError: httpx.ReadError: 
Error while getting Updates: httpx.ReadError: 
No error handlers are registered, logging exception.
Traceback (most recent call last):
  File "/root/jupyter-env/lib/python3.12/site-packages/httpx/_transports/default.py", line 66, in map_httpcore_exceptions
    yield
  File "/root/jupyter-env/lib/python3.12/site-packages/httpx/_transports/default.py", line 366, in handle_async_request
    resp = await self._pool.handle_async_request(req)
           ^^^^^^^^^^^^^^^^^^^^^^^^^^^^^^^^^^^^^^^^^^
  File "/root/jupyter-env/lib/python3.12/site-packages/httpcore/_async/connection_pool.py", line 256, in handle_async_request
    raise exc from None
  File "/root/jupyter-env/lib/python3.12/site-packages/httpcore/_async/connection_pool.py", line 236, in handle_async_request
    response = await connection.handle_async_request(
               ^^^^^^^^^^^^^^^^^^^^^^^^^^^^^^^^^^^^^^
  File "/root/jupyter-env/lib/python3.12/site-packages/httpcore/_async/connection.py", line 103, in handle_async_request
    return await self._connection.handle_async_request(request)
           ^^^^^^^^^^^^^^^^^^^^^^^^^^^^^^^^^^^^^^^^^^^^^^^^^^^^
  File "/root/jupyter-env/lib/python3.12/site-packages/httpcore/_async/http11.py", line 136, in handle_async_request
    raise exc
  File "/root/jupyter-env/lib/python3.12/site-packages/httpcore/_async/http11.py", line 106, in handle_async_request
    ) = await self._receive_response_headers(**kwargs)
        ^^^^^^^^^^^^^^^^^^^^^^^^^^^^^^^^^^^^^^^^^^^^^^
  File "/root/jupyter-env/lib/python3.12/site-packages/httpcore/_async/http11.py", line 177, in _receive_response_headers
    event = await self._receive_event(timeout=timeout)
            ^^^^^^^^^^^^^^^^^^^^^^^^^^^^^^^^^^^^^^^^^^
  File "/root/jupyter-env/lib/python3.12/site-packages/httpcore/_async/http11.py", line 217, in _receive_event
    data = await self._network_stream.read(
           ^^^^^^^^^^^^^^^^^^^^^^^^^^^^^^^^
  File "/root/jupyter-env/lib/python3.12/site-packages/httpcore/_backends/anyio.py", line 32, in read
    with map_exceptions(exc_map):
  File "/usr/lib/python3.12/contextlib.py", line 158, in __exit__
    self.gen.throw(value)
  File "/root/jupyter-env/lib/python3.12/site-packages/httpcore/_exceptions.py", line 14, in map_exceptions
    raise to_exc(exc) from exc
httpcore.ReadError

The above exception was the direct cause of the following exception:

Traceback (most recent call last):
  File "/root/jupyter-env/lib/python3.12/site-packages/telegram/request/_httpxrequest.py", line 268, in do_request
    res = await self._client.request(
          ^^^^^^^^^^^^^^^^^^^^^^^^^^^
  File "/root/jupyter-env/lib/python3.12/site-packages/httpx/_client.py", line 1530, in request
    return await self.send(request, auth=auth, follow_redirects=follow_redirects)
           ^^^^^^^^^^^^^^^^^^^^^^^^^^^^^^^^^^^^^^^^^^^^^^^^^^^^^^^^^^^^^^^^^^^^^^
  File "/root/jupyter-env/lib/python3.12/site-packages/httpx/_client.py", line 1617, in send
    response = await self._send_handling_auth(
               ^^^^^^^^^^^^^^^^^^^^^^^^^^^^^^^
  File "/root/jupyter-env/lib/python3.12/site-packages/httpx/_client.py", line 1645, in _send_handling_auth
    response = await self._send_handling_redirects(
               ^^^^^^^^^^^^^^^^^^^^^^^^^^^^^^^^^^^^
  File "/root/jupyter-env/lib/python3.12/site-packages/httpx/_client.py", line 1682, in _send_handling_redirects
    response = await self._send_single_request(request)
               ^^^^^^^^^^^^^^^^^^^^^^^^^^^^^^^^^^^^^^^^
  File "/root/jupyter-env/lib/python3.12/site-packages/httpx/_client.py", line 1719, in _send_single_request
    response = await transport.handle_async_request(request)
               ^^^^^^^^^^^^^^^^^^^^^^^^^^^^^^^^^^^^^^^^^^^^^
  File "/root/jupyter-env/lib/python3.12/site-packages/httpx/_transports/default.py", line 365, in handle_async_request
    with map_httpcore_exceptions():
  File "/usr/lib/python3.12/contextlib.py", line 158, in __exit__
    self.gen.throw(value)
  File "/root/jupyter-env/lib/python3.12/site-packages/httpx/_transports/default.py", line 83, in map_httpcore_exceptions
    raise mapped_exc(message) from exc
httpx.ReadError

The above exception was the direct cause of the following exception:

Traceback (most recent call last):
  File "/root/jupyter-env/lib/python3.12/site-packages/telegram/ext/_updater.py", line 688, in _network_loop_retry
    if not await action_cb():
           ^^^^^^^^^^^^^^^^^
  File "/root/jupyter-env/lib/python3.12/site-packages/telegram/ext/_updater.py", line 384, in polling_action_cb
    raise exc
  File "/root/jupyter-env/lib/python3.12/site-packages/telegram/ext/_updater.py", line 373, in polling_action_cb
    updates = await self.bot.get_updates(
              ^^^^^^^^^^^^^^^^^^^^^^^^^^^
  File "/root/jupyter-env/lib/python3.12/site-packages/telegram/ext/_extbot.py", line 558, in get_updates
    updates = await super().get_updates(
              ^^^^^^^^^^^^^^^^^^^^^^^^^^
  File "/root/jupyter-env/lib/python3.12/site-packages/telegram/_bot.py", line 525, in decorator
    result = await func(self, *args, **kwargs)  # skipcq: PYL-E1102
             ^^^^^^^^^^^^^^^^^^^^^^^^^^^^^^^^^
  File "/root/jupyter-env/lib/python3.12/site-packages/telegram/_bot.py", line 3584, in get_updates
    await self._post(
  File "/root/jupyter-env/lib/python3.12/site-packages/telegram/_bot.py", line 613, in _post
    return await self._do_post(
           ^^^^^^^^^^^^^^^^^^^^
  File "/root/jupyter-env/lib/python3.12/site-packages/telegram/ext/_extbot.py", line 340, in _do_post
    return await super()._do_post(
           ^^^^^^^^^^^^^^^^^^^^^^^
  File "/root/jupyter-env/lib/python3.12/site-packages/telegram/_bot.py", line 641, in _do_post
    return await request.post(
           ^^^^^^^^^^^^^^^^^^^
  File "/root/jupyter-env/lib/python3.12/site-packages/telegram/request/_baserequest.py", line 200, in post
    result = await self._request_wrapper(
             ^^^^^^^^^^^^^^^^^^^^^^^^^^^^
  File "/root/jupyter-env/lib/python3.12/site-packages/telegram/request/_baserequest.py", line 340, in _request_wrapper
    raise exc
  File "/root/jupyter-env/lib/python3.12/site-packages/telegram/request/_baserequest.py", line 330, in _request_wrapper
    code, payload = await self.do_request(
                    ^^^^^^^^^^^^^^^^^^^^^^
  File "/root/jupyter-env/lib/python3.12/site-packages/telegram/request/_httpxrequest.py", line 292, in do_request
    raise NetworkError(f"httpx.{err.__class__.__name__}: {err}") from err
telegram.error.NetworkError: httpx.ReadError: 
Error while getting Updates: Bad Gateway
No error handlers are registered, logging exception.
Traceback (most recent call last):
  File "/root/jupyter-env/lib/python3.12/site-packages/telegram/ext/_updater.py", line 688, in _network_loop_retry
    if not await action_cb():
           ^^^^^^^^^^^^^^^^^
  File "/root/jupyter-env/lib/python3.12/site-packages/telegram/ext/_updater.py", line 384, in polling_action_cb
    raise exc
  File "/root/jupyter-env/lib/python3.12/site-packages/telegram/ext/_updater.py", line 373, in polling_action_cb
    updates = await self.bot.get_updates(
              ^^^^^^^^^^^^^^^^^^^^^^^^^^^
  File "/root/jupyter-env/lib/python3.12/site-packages/telegram/ext/_extbot.py", line 558, in get_updates
    updates = await super().get_updates(
              ^^^^^^^^^^^^^^^^^^^^^^^^^^
  File "/root/jupyter-env/lib/python3.12/site-packages/telegram/_bot.py", line 525, in decorator
    result = await func(self, *args, **kwargs)  # skipcq: PYL-E1102
             ^^^^^^^^^^^^^^^^^^^^^^^^^^^^^^^^^
  File "/root/jupyter-env/lib/python3.12/site-packages/telegram/_bot.py", line 3584, in get_updates
    await self._post(
  File "/root/jupyter-env/lib/python3.12/site-packages/telegram/_bot.py", line 613, in _post
    return await self._do_post(
           ^^^^^^^^^^^^^^^^^^^^
  File "/root/jupyter-env/lib/python3.12/site-packages/telegram/ext/_extbot.py", line 340, in _do_post
    return await super()._do_post(
           ^^^^^^^^^^^^^^^^^^^^^^^
  File "/root/jupyter-env/lib/python3.12/site-packages/telegram/_bot.py", line 641, in _do_post
    return await request.post(
           ^^^^^^^^^^^^^^^^^^^
  File "/root/jupyter-env/lib/python3.12/site-packages/telegram/request/_baserequest.py", line 200, in post
    result = await self._request_wrapper(
             ^^^^^^^^^^^^^^^^^^^^^^^^^^^^
  File "/root/jupyter-env/lib/python3.12/site-packages/telegram/request/_baserequest.py", line 383, in _request_wrapper
    raise NetworkError(description or "Bad Gateway")
telegram.error.NetworkError: Bad Gateway
Error while getting Updates: Bad Gateway
No error handlers are registered, logging exception.
Traceback (most recent call last):
  File "/root/jupyter-env/lib/python3.12/site-packages/telegram/ext/_updater.py", line 688, in _network_loop_retry
    if not await action_cb():
           ^^^^^^^^^^^^^^^^^
  File "/root/jupyter-env/lib/python3.12/site-packages/telegram/ext/_updater.py", line 384, in polling_action_cb
    raise exc
  File "/root/jupyter-env/lib/python3.12/site-packages/telegram/ext/_updater.py", line 373, in polling_action_cb
    updates = await self.bot.get_updates(
              ^^^^^^^^^^^^^^^^^^^^^^^^^^^
  File "/root/jupyter-env/lib/python3.12/site-packages/telegram/ext/_extbot.py", line 558, in get_updates
    updates = await super().get_updates(
              ^^^^^^^^^^^^^^^^^^^^^^^^^^
  File "/root/jupyter-env/lib/python3.12/site-packages/telegram/_bot.py", line 525, in decorator
    result = await func(self, *args, **kwargs)  # skipcq: PYL-E1102
             ^^^^^^^^^^^^^^^^^^^^^^^^^^^^^^^^^
  File "/root/jupyter-env/lib/python3.12/site-packages/telegram/_bot.py", line 3584, in get_updates
    await self._post(
  File "/root/jupyter-env/lib/python3.12/site-packages/telegram/_bot.py", line 613, in _post
    return await self._do_post(
           ^^^^^^^^^^^^^^^^^^^^
  File "/root/jupyter-env/lib/python3.12/site-packages/telegram/ext/_extbot.py", line 340, in _do_post
    return await super()._do_post(
           ^^^^^^^^^^^^^^^^^^^^^^^
  File "/root/jupyter-env/lib/python3.12/site-packages/telegram/_bot.py", line 641, in _do_post
    return await request.post(
           ^^^^^^^^^^^^^^^^^^^
  File "/root/jupyter-env/lib/python3.12/site-packages/telegram/request/_baserequest.py", line 200, in post
    result = await self._request_wrapper(
             ^^^^^^^^^^^^^^^^^^^^^^^^^^^^
  File "/root/jupyter-env/lib/python3.12/site-packages/telegram/request/_baserequest.py", line 383, in _request_wrapper
    raise NetworkError(description or "Bad Gateway")
telegram.error.NetworkError: Bad Gateway
Error while getting Updates: Bad Gateway
No error handlers are registered, logging exception.
Traceback (most recent call last):
  File "/root/jupyter-env/lib/python3.12/site-packages/telegram/ext/_updater.py", line 688, in _network_loop_retry
    if not await action_cb():
           ^^^^^^^^^^^^^^^^^
  File "/root/jupyter-env/lib/python3.12/site-packages/telegram/ext/_updater.py", line 384, in polling_action_cb
    raise exc
  File "/root/jupyter-env/lib/python3.12/site-packages/telegram/ext/_updater.py", line 373, in polling_action_cb
    updates = await self.bot.get_updates(
              ^^^^^^^^^^^^^^^^^^^^^^^^^^^
  File "/root/jupyter-env/lib/python3.12/site-packages/telegram/ext/_extbot.py", line 558, in get_updates
    updates = await super().get_updates(
              ^^^^^^^^^^^^^^^^^^^^^^^^^^
  File "/root/jupyter-env/lib/python3.12/site-packages/telegram/_bot.py", line 525, in decorator
    result = await func(self, *args, **kwargs)  # skipcq: PYL-E1102
             ^^^^^^^^^^^^^^^^^^^^^^^^^^^^^^^^^
  File "/root/jupyter-env/lib/python3.12/site-packages/telegram/_bot.py", line 3584, in get_updates
    await self._post(
  File "/root/jupyter-env/lib/python3.12/site-packages/telegram/_bot.py", line 613, in _post
    return await self._do_post(
           ^^^^^^^^^^^^^^^^^^^^
  File "/root/jupyter-env/lib/python3.12/site-packages/telegram/ext/_extbot.py", line 340, in _do_post
    return await super()._do_post(
           ^^^^^^^^^^^^^^^^^^^^^^^
  File "/root/jupyter-env/lib/python3.12/site-packages/telegram/_bot.py", line 641, in _do_post
    return await request.post(
           ^^^^^^^^^^^^^^^^^^^
  File "/root/jupyter-env/lib/python3.12/site-packages/telegram/request/_baserequest.py", line 200, in post
    result = await self._request_wrapper(
             ^^^^^^^^^^^^^^^^^^^^^^^^^^^^
  File "/root/jupyter-env/lib/python3.12/site-packages/telegram/request/_baserequest.py", line 383, in _request_wrapper
    raise NetworkError(description or "Bad Gateway")
telegram.error.NetworkError: Bad Gateway
Error while getting Updates: Bad Gateway
No error handlers are registered, logging exception.
Traceback (most recent call last):
  File "/root/jupyter-env/lib/python3.12/site-packages/telegram/ext/_updater.py", line 688, in _network_loop_retry
    if not await action_cb():
           ^^^^^^^^^^^^^^^^^
  File "/root/jupyter-env/lib/python3.12/site-packages/telegram/ext/_updater.py", line 384, in polling_action_cb
    raise exc
  File "/root/jupyter-env/lib/python3.12/site-packages/telegram/ext/_updater.py", line 373, in polling_action_cb
    updates = await self.bot.get_updates(
              ^^^^^^^^^^^^^^^^^^^^^^^^^^^
  File "/root/jupyter-env/lib/python3.12/site-packages/telegram/ext/_extbot.py", line 558, in get_updates
    updates = await super().get_updates(
              ^^^^^^^^^^^^^^^^^^^^^^^^^^
  File "/root/jupyter-env/lib/python3.12/site-packages/telegram/_bot.py", line 525, in decorator
    result = await func(self, *args, **kwargs)  # skipcq: PYL-E1102
             ^^^^^^^^^^^^^^^^^^^^^^^^^^^^^^^^^
  File "/root/jupyter-env/lib/python3.12/site-packages/telegram/_bot.py", line 3584, in get_updates
    await self._post(
  File "/root/jupyter-env/lib/python3.12/site-packages/telegram/_bot.py", line 613, in _post
    return await self._do_post(
           ^^^^^^^^^^^^^^^^^^^^
  File "/root/jupyter-env/lib/python3.12/site-packages/telegram/ext/_extbot.py", line 340, in _do_post
    return await super()._do_post(
           ^^^^^^^^^^^^^^^^^^^^^^^
  File "/root/jupyter-env/lib/python3.12/site-packages/telegram/_bot.py", line 641, in _do_post
    return await request.post(
           ^^^^^^^^^^^^^^^^^^^
  File "/root/jupyter-env/lib/python3.12/site-packages/telegram/request/_baserequest.py", line 200, in post
    result = await self._request_wrapper(
             ^^^^^^^^^^^^^^^^^^^^^^^^^^^^
  File "/root/jupyter-env/lib/python3.12/site-packages/telegram/request/_baserequest.py", line 383, in _request_wrapper
    raise NetworkError(description or "Bad Gateway")
telegram.error.NetworkError: Bad Gateway
Error while getting Updates: httpx.ReadError: 
No error handlers are registered, logging exception.
Traceback (most recent call last):
  File "/root/jupyter-env/lib/python3.12/site-packages/httpx/_transports/default.py", line 66, in map_httpcore_exceptions
    yield
  File "/root/jupyter-env/lib/python3.12/site-packages/httpx/_transports/default.py", line 366, in handle_async_request
    resp = await self._pool.handle_async_request(req)
           ^^^^^^^^^^^^^^^^^^^^^^^^^^^^^^^^^^^^^^^^^^
  File "/root/jupyter-env/lib/python3.12/site-packages/httpcore/_async/connection_pool.py", line 256, in handle_async_request
    raise exc from None
  File "/root/jupyter-env/lib/python3.12/site-packages/httpcore/_async/connection_pool.py", line 236, in handle_async_request
    response = await connection.handle_async_request(
               ^^^^^^^^^^^^^^^^^^^^^^^^^^^^^^^^^^^^^^
  File "/root/jupyter-env/lib/python3.12/site-packages/httpcore/_async/connection.py", line 103, in handle_async_request
    return await self._connection.handle_async_request(request)
           ^^^^^^^^^^^^^^^^^^^^^^^^^^^^^^^^^^^^^^^^^^^^^^^^^^^^
  File "/root/jupyter-env/lib/python3.12/site-packages/httpcore/_async/http11.py", line 136, in handle_async_request
    raise exc
  File "/root/jupyter-env/lib/python3.12/site-packages/httpcore/_async/http11.py", line 106, in handle_async_request
    ) = await self._receive_response_headers(**kwargs)
        ^^^^^^^^^^^^^^^^^^^^^^^^^^^^^^^^^^^^^^^^^^^^^^
  File "/root/jupyter-env/lib/python3.12/site-packages/httpcore/_async/http11.py", line 177, in _receive_response_headers
    event = await self._receive_event(timeout=timeout)
            ^^^^^^^^^^^^^^^^^^^^^^^^^^^^^^^^^^^^^^^^^^
  File "/root/jupyter-env/lib/python3.12/site-packages/httpcore/_async/http11.py", line 217, in _receive_event
    data = await self._network_stream.read(
           ^^^^^^^^^^^^^^^^^^^^^^^^^^^^^^^^
  File "/root/jupyter-env/lib/python3.12/site-packages/httpcore/_backends/anyio.py", line 32, in read
    with map_exceptions(exc_map):
  File "/usr/lib/python3.12/contextlib.py", line 158, in __exit__
    self.gen.throw(value)
  File "/root/jupyter-env/lib/python3.12/site-packages/httpcore/_exceptions.py", line 14, in map_exceptions
    raise to_exc(exc) from exc
httpcore.ReadError

The above exception was the direct cause of the following exception:

Traceback (most recent call last):
  File "/root/jupyter-env/lib/python3.12/site-packages/telegram/request/_httpxrequest.py", line 268, in do_request
    res = await self._client.request(
          ^^^^^^^^^^^^^^^^^^^^^^^^^^^
  File "/root/jupyter-env/lib/python3.12/site-packages/httpx/_client.py", line 1530, in request
    return await self.send(request, auth=auth, follow_redirects=follow_redirects)
           ^^^^^^^^^^^^^^^^^^^^^^^^^^^^^^^^^^^^^^^^^^^^^^^^^^^^^^^^^^^^^^^^^^^^^^
  File "/root/jupyter-env/lib/python3.12/site-packages/httpx/_client.py", line 1617, in send
    response = await self._send_handling_auth(
               ^^^^^^^^^^^^^^^^^^^^^^^^^^^^^^^
  File "/root/jupyter-env/lib/python3.12/site-packages/httpx/_client.py", line 1645, in _send_handling_auth
    response = await self._send_handling_redirects(
               ^^^^^^^^^^^^^^^^^^^^^^^^^^^^^^^^^^^^
  File "/root/jupyter-env/lib/python3.12/site-packages/httpx/_client.py", line 1682, in _send_handling_redirects
    response = await self._send_single_request(request)
               ^^^^^^^^^^^^^^^^^^^^^^^^^^^^^^^^^^^^^^^^
  File "/root/jupyter-env/lib/python3.12/site-packages/httpx/_client.py", line 1719, in _send_single_request
    response = await transport.handle_async_request(request)
               ^^^^^^^^^^^^^^^^^^^^^^^^^^^^^^^^^^^^^^^^^^^^^
  File "/root/jupyter-env/lib/python3.12/site-packages/httpx/_transports/default.py", line 365, in handle_async_request
    with map_httpcore_exceptions():
  File "/usr/lib/python3.12/contextlib.py", line 158, in __exit__
    self.gen.throw(value)
  File "/root/jupyter-env/lib/python3.12/site-packages/httpx/_transports/default.py", line 83, in map_httpcore_exceptions
    raise mapped_exc(message) from exc
httpx.ReadError

The above exception was the direct cause of the following exception:

Traceback (most recent call last):
  File "/root/jupyter-env/lib/python3.12/site-packages/telegram/ext/_updater.py", line 688, in _network_loop_retry
    if not await action_cb():
           ^^^^^^^^^^^^^^^^^
  File "/root/jupyter-env/lib/python3.12/site-packages/telegram/ext/_updater.py", line 384, in polling_action_cb
    raise exc
  File "/root/jupyter-env/lib/python3.12/site-packages/telegram/ext/_updater.py", line 373, in polling_action_cb
    updates = await self.bot.get_updates(
              ^^^^^^^^^^^^^^^^^^^^^^^^^^^
  File "/root/jupyter-env/lib/python3.12/site-packages/telegram/ext/_extbot.py", line 558, in get_updates
    updates = await super().get_updates(
              ^^^^^^^^^^^^^^^^^^^^^^^^^^
  File "/root/jupyter-env/lib/python3.12/site-packages/telegram/_bot.py", line 525, in decorator
    result = await func(self, *args, **kwargs)  # skipcq: PYL-E1102
             ^^^^^^^^^^^^^^^^^^^^^^^^^^^^^^^^^
  File "/root/jupyter-env/lib/python3.12/site-packages/telegram/_bot.py", line 3584, in get_updates
    await self._post(
  File "/root/jupyter-env/lib/python3.12/site-packages/telegram/_bot.py", line 613, in _post
    return await self._do_post(
           ^^^^^^^^^^^^^^^^^^^^
  File "/root/jupyter-env/lib/python3.12/site-packages/telegram/ext/_extbot.py", line 340, in _do_post
    return await super()._do_post(
           ^^^^^^^^^^^^^^^^^^^^^^^
  File "/root/jupyter-env/lib/python3.12/site-packages/telegram/_bot.py", line 641, in _do_post
    return await request.post(
           ^^^^^^^^^^^^^^^^^^^
  File "/root/jupyter-env/lib/python3.12/site-packages/telegram/request/_baserequest.py", line 200, in post
    result = await self._request_wrapper(
             ^^^^^^^^^^^^^^^^^^^^^^^^^^^^
  File "/root/jupyter-env/lib/python3.12/site-packages/telegram/request/_baserequest.py", line 340, in _request_wrapper
    raise exc
  File "/root/jupyter-env/lib/python3.12/site-packages/telegram/request/_baserequest.py", line 330, in _request_wrapper
    code, payload = await self.do_request(
                    ^^^^^^^^^^^^^^^^^^^^^^
  File "/root/jupyter-env/lib/python3.12/site-packages/telegram/request/_httpxrequest.py", line 292, in do_request
    raise NetworkError(f"httpx.{err.__class__.__name__}: {err}") from err
telegram.error.NetworkError: httpx.ReadError: 
Error while getting Updates: httpx.ReadError: 
No error handlers are registered, logging exception.
Traceback (most recent call last):
  File "/root/jupyter-env/lib/python3.12/site-packages/httpx/_transports/default.py", line 66, in map_httpcore_exceptions
    yield
  File "/root/jupyter-env/lib/python3.12/site-packages/httpx/_transports/default.py", line 366, in handle_async_request
    resp = await self._pool.handle_async_request(req)
           ^^^^^^^^^^^^^^^^^^^^^^^^^^^^^^^^^^^^^^^^^^
  File "/root/jupyter-env/lib/python3.12/site-packages/httpcore/_async/connection_pool.py", line 256, in handle_async_request
    raise exc from None
  File "/root/jupyter-env/lib/python3.12/site-packages/httpcore/_async/connection_pool.py", line 236, in handle_async_request
    response = await connection.handle_async_request(
               ^^^^^^^^^^^^^^^^^^^^^^^^^^^^^^^^^^^^^^
  File "/root/jupyter-env/lib/python3.12/site-packages/httpcore/_async/connection.py", line 103, in handle_async_request
    return await self._connection.handle_async_request(request)
           ^^^^^^^^^^^^^^^^^^^^^^^^^^^^^^^^^^^^^^^^^^^^^^^^^^^^
  File "/root/jupyter-env/lib/python3.12/site-packages/httpcore/_async/http11.py", line 136, in handle_async_request
    raise exc
  File "/root/jupyter-env/lib/python3.12/site-packages/httpcore/_async/http11.py", line 106, in handle_async_request
    ) = await self._receive_response_headers(**kwargs)
        ^^^^^^^^^^^^^^^^^^^^^^^^^^^^^^^^^^^^^^^^^^^^^^
  File "/root/jupyter-env/lib/python3.12/site-packages/httpcore/_async/http11.py", line 177, in _receive_response_headers
    event = await self._receive_event(timeout=timeout)
            ^^^^^^^^^^^^^^^^^^^^^^^^^^^^^^^^^^^^^^^^^^
  File "/root/jupyter-env/lib/python3.12/site-packages/httpcore/_async/http11.py", line 217, in _receive_event
    data = await self._network_stream.read(
           ^^^^^^^^^^^^^^^^^^^^^^^^^^^^^^^^
  File "/root/jupyter-env/lib/python3.12/site-packages/httpcore/_backends/anyio.py", line 32, in read
    with map_exceptions(exc_map):
  File "/usr/lib/python3.12/contextlib.py", line 158, in __exit__
    self.gen.throw(value)
  File "/root/jupyter-env/lib/python3.12/site-packages/httpcore/_exceptions.py", line 14, in map_exceptions
    raise to_exc(exc) from exc
httpcore.ReadError

The above exception was the direct cause of the following exception:

Traceback (most recent call last):
  File "/root/jupyter-env/lib/python3.12/site-packages/telegram/request/_httpxrequest.py", line 268, in do_request
    res = await self._client.request(
          ^^^^^^^^^^^^^^^^^^^^^^^^^^^
  File "/root/jupyter-env/lib/python3.12/site-packages/httpx/_client.py", line 1530, in request
    return await self.send(request, auth=auth, follow_redirects=follow_redirects)
           ^^^^^^^^^^^^^^^^^^^^^^^^^^^^^^^^^^^^^^^^^^^^^^^^^^^^^^^^^^^^^^^^^^^^^^
  File "/root/jupyter-env/lib/python3.12/site-packages/httpx/_client.py", line 1617, in send
    response = await self._send_handling_auth(
               ^^^^^^^^^^^^^^^^^^^^^^^^^^^^^^^
  File "/root/jupyter-env/lib/python3.12/site-packages/httpx/_client.py", line 1645, in _send_handling_auth
    response = await self._send_handling_redirects(
               ^^^^^^^^^^^^^^^^^^^^^^^^^^^^^^^^^^^^
  File "/root/jupyter-env/lib/python3.12/site-packages/httpx/_client.py", line 1682, in _send_handling_redirects
    response = await self._send_single_request(request)
               ^^^^^^^^^^^^^^^^^^^^^^^^^^^^^^^^^^^^^^^^
  File "/root/jupyter-env/lib/python3.12/site-packages/httpx/_client.py", line 1719, in _send_single_request
    response = await transport.handle_async_request(request)
               ^^^^^^^^^^^^^^^^^^^^^^^^^^^^^^^^^^^^^^^^^^^^^
  File "/root/jupyter-env/lib/python3.12/site-packages/httpx/_transports/default.py", line 365, in handle_async_request
    with map_httpcore_exceptions():
  File "/usr/lib/python3.12/contextlib.py", line 158, in __exit__
    self.gen.throw(value)
  File "/root/jupyter-env/lib/python3.12/site-packages/httpx/_transports/default.py", line 83, in map_httpcore_exceptions
    raise mapped_exc(message) from exc
httpx.ReadError

The above exception was the direct cause of the following exception:

Traceback (most recent call last):
  File "/root/jupyter-env/lib/python3.12/site-packages/telegram/ext/_updater.py", line 688, in _network_loop_retry
    if not await action_cb():
           ^^^^^^^^^^^^^^^^^
  File "/root/jupyter-env/lib/python3.12/site-packages/telegram/ext/_updater.py", line 384, in polling_action_cb
    raise exc
  File "/root/jupyter-env/lib/python3.12/site-packages/telegram/ext/_updater.py", line 373, in polling_action_cb
    updates = await self.bot.get_updates(
              ^^^^^^^^^^^^^^^^^^^^^^^^^^^
  File "/root/jupyter-env/lib/python3.12/site-packages/telegram/ext/_extbot.py", line 558, in get_updates
    updates = await super().get_updates(
              ^^^^^^^^^^^^^^^^^^^^^^^^^^
  File "/root/jupyter-env/lib/python3.12/site-packages/telegram/_bot.py", line 525, in decorator
    result = await func(self, *args, **kwargs)  # skipcq: PYL-E1102
             ^^^^^^^^^^^^^^^^^^^^^^^^^^^^^^^^^
  File "/root/jupyter-env/lib/python3.12/site-packages/telegram/_bot.py", line 3584, in get_updates
    await self._post(
  File "/root/jupyter-env/lib/python3.12/site-packages/telegram/_bot.py", line 613, in _post
    return await self._do_post(
           ^^^^^^^^^^^^^^^^^^^^
  File "/root/jupyter-env/lib/python3.12/site-packages/telegram/ext/_extbot.py", line 340, in _do_post
    return await super()._do_post(
           ^^^^^^^^^^^^^^^^^^^^^^^
  File "/root/jupyter-env/lib/python3.12/site-packages/telegram/_bot.py", line 641, in _do_post
    return await request.post(
           ^^^^^^^^^^^^^^^^^^^
  File "/root/jupyter-env/lib/python3.12/site-packages/telegram/request/_baserequest.py", line 200, in post
    result = await self._request_wrapper(
             ^^^^^^^^^^^^^^^^^^^^^^^^^^^^
  File "/root/jupyter-env/lib/python3.12/site-packages/telegram/request/_baserequest.py", line 340, in _request_wrapper
    raise exc
  File "/root/jupyter-env/lib/python3.12/site-packages/telegram/request/_baserequest.py", line 330, in _request_wrapper
    code, payload = await self.do_request(
                    ^^^^^^^^^^^^^^^^^^^^^^
  File "/root/jupyter-env/lib/python3.12/site-packages/telegram/request/_httpxrequest.py", line 292, in do_request
    raise NetworkError(f"httpx.{err.__class__.__name__}: {err}") from err
telegram.error.NetworkError: httpx.ReadError: 
No error handlers are registered, logging exception.
Traceback (most recent call last):
  File "/root/jupyter-env/lib/python3.12/site-packages/telegram/ext/_application.py", line 1234, in process_update
    await coroutine
  File "/root/jupyter-env/lib/python3.12/site-packages/telegram/ext/_basehandler.py", line 157, in handle_update
    return await self.callback(update, context)
           ^^^^^^^^^^^^^^^^^^^^^^^^^^^^^^^^^^^^
  File "/root/jupyter-env/project_outline/client_bot/keyboards/user_agreement.py", line 53, in agreement_button_handler
    reply_markup = get_main_menu()
                   ^^^^^^^^^^^^^^^
TypeError: get_main_menu() missing 1 required positional argument: 'user_choice'
No error handlers are registered, logging exception.
Traceback (most recent call last):
  File "/root/jupyter-env/lib/python3.12/site-packages/telegram/ext/_application.py", line 1234, in process_update
    await coroutine
  File "/root/jupyter-env/lib/python3.12/site-packages/telegram/ext/_basehandler.py", line 157, in handle_update
    return await self.callback(update, context)
           ^^^^^^^^^^^^^^^^^^^^^^^^^^^^^^^^^^^^
  File "/root/jupyter-env/project_outline/client_bot/keyboards/user_agreement.py", line 53, in agreement_button_handler
    reply_markup = get_main_menu()
                   ^^^^^^^^^^^^^^^
TypeError: get_main_menu() missing 1 required positional argument: 'user_choice'
No error handlers are registered, logging exception.
Traceback (most recent call last):
  File "/root/jupyter-env/lib/python3.12/site-packages/telegram/ext/_application.py", line 1234, in process_update
    await coroutine
  File "/root/jupyter-env/lib/python3.12/site-packages/telegram/ext/_basehandler.py", line 157, in handle_update
    return await self.callback(update, context)
           ^^^^^^^^^^^^^^^^^^^^^^^^^^^^^^^^^^^^
  File "/root/jupyter-env/project_outline/client_bot/keyboards/user_agreement.py", line 53, in agreement_button_handler
    reply_markup = get_main_menu()
                   ^^^^^^^^^^^^^^^
TypeError: get_main_menu() missing 1 required positional argument: 'user_choice'
is_agreement_accepted True
is_agreement_accepted True
is_agreement_accepted None
is_agreement_accepted True
is_agreement_accepted True
is_agreement_accepted None
No error handlers are registered, logging exception.
Traceback (most recent call last):
  File "/root/jupyter-env/lib/python3.12/site-packages/telegram/ext/_application.py", line 1234, in process_update
    await coroutine
  File "/root/jupyter-env/lib/python3.12/site-packages/telegram/ext/_basehandler.py", line 157, in handle_update
    return await self.callback(update, context)
           ^^^^^^^^^^^^^^^^^^^^^^^^^^^^^^^^^^^^
  File "/root/jupyter-env/project_outline/client_bot/keyboards/user_agreement.py", line 35, in agreement_button_handler
    await query.answer()
  File "/root/jupyter-env/lib/python3.12/site-packages/telegram/_callbackquery.py", line 180, in answer
    return await self.get_bot().answer_callback_query(
           ^^^^^^^^^^^^^^^^^^^^^^^^^^^^^^^^^^^^^^^^^^^
  File "/root/jupyter-env/lib/python3.12/site-packages/telegram/ext/_extbot.py", line 778, in answer_callback_query
    return await super().answer_callback_query(
           ^^^^^^^^^^^^^^^^^^^^^^^^^^^^^^^^^^^^
  File "/root/jupyter-env/lib/python3.12/site-packages/telegram/_bot.py", line 525, in decorator
    result = await func(self, *args, **kwargs)  # skipcq: PYL-E1102
             ^^^^^^^^^^^^^^^^^^^^^^^^^^^^^^^^^
  File "/root/jupyter-env/lib/python3.12/site-packages/telegram/_bot.py", line 3213, in answer_callback_query
    return await self._post(
           ^^^^^^^^^^^^^^^^^
  File "/root/jupyter-env/lib/python3.12/site-packages/telegram/_bot.py", line 613, in _post
    return await self._do_post(
           ^^^^^^^^^^^^^^^^^^^^
  File "/root/jupyter-env/lib/python3.12/site-packages/telegram/ext/_extbot.py", line 340, in _do_post
    return await super()._do_post(
           ^^^^^^^^^^^^^^^^^^^^^^^
  File "/root/jupyter-env/lib/python3.12/site-packages/telegram/_bot.py", line 641, in _do_post
    return await request.post(
           ^^^^^^^^^^^^^^^^^^^
  File "/root/jupyter-env/lib/python3.12/site-packages/telegram/request/_baserequest.py", line 200, in post
    result = await self._request_wrapper(
             ^^^^^^^^^^^^^^^^^^^^^^^^^^^^
  File "/root/jupyter-env/lib/python3.12/site-packages/telegram/request/_baserequest.py", line 379, in _request_wrapper
    raise BadRequest(message)
telegram.error.BadRequest: Query is too old and response timeout expired or query id is invalid
/root/jupyter-env/lib/python3.12/site-packages/urllib3/connectionpool.py:1097: InsecureRequestWarning: Unverified HTTPS request is being made to host '193.187.174.24'. Adding certificate verification is strongly advised. See: https://urllib3.readthedocs.io/en/latest/advanced-usage.html#tls-warnings
  warnings.warn(
No error handlers are registered, logging exception.
Traceback (most recent call last):
  File "/root/jupyter-env/lib/python3.12/site-packages/httpx/_transports/default.py", line 66, in map_httpcore_exceptions
    yield
  File "/root/jupyter-env/lib/python3.12/site-packages/httpx/_transports/default.py", line 366, in handle_async_request
    resp = await self._pool.handle_async_request(req)
           ^^^^^^^^^^^^^^^^^^^^^^^^^^^^^^^^^^^^^^^^^^
  File "/root/jupyter-env/lib/python3.12/site-packages/httpcore/_async/connection_pool.py", line 256, in handle_async_request
    raise exc from None
  File "/root/jupyter-env/lib/python3.12/site-packages/httpcore/_async/connection_pool.py", line 236, in handle_async_request
    response = await connection.handle_async_request(
               ^^^^^^^^^^^^^^^^^^^^^^^^^^^^^^^^^^^^^^
  File "/root/jupyter-env/lib/python3.12/site-packages/httpcore/_async/connection.py", line 103, in handle_async_request
    return await self._connection.handle_async_request(request)
           ^^^^^^^^^^^^^^^^^^^^^^^^^^^^^^^^^^^^^^^^^^^^^^^^^^^^
  File "/root/jupyter-env/lib/python3.12/site-packages/httpcore/_async/http11.py", line 136, in handle_async_request
    raise exc
  File "/root/jupyter-env/lib/python3.12/site-packages/httpcore/_async/http11.py", line 106, in handle_async_request
    ) = await self._receive_response_headers(**kwargs)
        ^^^^^^^^^^^^^^^^^^^^^^^^^^^^^^^^^^^^^^^^^^^^^^
  File "/root/jupyter-env/lib/python3.12/site-packages/httpcore/_async/http11.py", line 177, in _receive_response_headers
    event = await self._receive_event(timeout=timeout)
            ^^^^^^^^^^^^^^^^^^^^^^^^^^^^^^^^^^^^^^^^^^
  File "/root/jupyter-env/lib/python3.12/site-packages/httpcore/_async/http11.py", line 217, in _receive_event
    data = await self._network_stream.read(
           ^^^^^^^^^^^^^^^^^^^^^^^^^^^^^^^^
  File "/root/jupyter-env/lib/python3.12/site-packages/httpcore/_backends/anyio.py", line 32, in read
    with map_exceptions(exc_map):
  File "/usr/lib/python3.12/contextlib.py", line 158, in __exit__
    self.gen.throw(value)
  File "/root/jupyter-env/lib/python3.12/site-packages/httpcore/_exceptions.py", line 14, in map_exceptions
    raise to_exc(exc) from exc
httpcore.ReadError

The above exception was the direct cause of the following exception:

Traceback (most recent call last):
  File "/root/jupyter-env/lib/python3.12/site-packages/telegram/request/_httpxrequest.py", line 268, in do_request
    res = await self._client.request(
          ^^^^^^^^^^^^^^^^^^^^^^^^^^^
  File "/root/jupyter-env/lib/python3.12/site-packages/httpx/_client.py", line 1530, in request
    return await self.send(request, auth=auth, follow_redirects=follow_redirects)
           ^^^^^^^^^^^^^^^^^^^^^^^^^^^^^^^^^^^^^^^^^^^^^^^^^^^^^^^^^^^^^^^^^^^^^^
  File "/root/jupyter-env/lib/python3.12/site-packages/httpx/_client.py", line 1617, in send
    response = await self._send_handling_auth(
               ^^^^^^^^^^^^^^^^^^^^^^^^^^^^^^^
  File "/root/jupyter-env/lib/python3.12/site-packages/httpx/_client.py", line 1645, in _send_handling_auth
    response = await self._send_handling_redirects(
               ^^^^^^^^^^^^^^^^^^^^^^^^^^^^^^^^^^^^
  File "/root/jupyter-env/lib/python3.12/site-packages/httpx/_client.py", line 1682, in _send_handling_redirects
    response = await self._send_single_request(request)
               ^^^^^^^^^^^^^^^^^^^^^^^^^^^^^^^^^^^^^^^^
  File "/root/jupyter-env/lib/python3.12/site-packages/httpx/_client.py", line 1719, in _send_single_request
    response = await transport.handle_async_request(request)
               ^^^^^^^^^^^^^^^^^^^^^^^^^^^^^^^^^^^^^^^^^^^^^
  File "/root/jupyter-env/lib/python3.12/site-packages/httpx/_transports/default.py", line 365, in handle_async_request
    with map_httpcore_exceptions():
  File "/usr/lib/python3.12/contextlib.py", line 158, in __exit__
    self.gen.throw(value)
  File "/root/jupyter-env/lib/python3.12/site-packages/httpx/_transports/default.py", line 83, in map_httpcore_exceptions
    raise mapped_exc(message) from exc
httpx.ReadError

The above exception was the direct cause of the following exception:

Traceback (most recent call last):
  File "/root/jupyter-env/lib/python3.12/site-packages/telegram/ext/_application.py", line 1234, in process_update
    await coroutine
  File "/root/jupyter-env/lib/python3.12/site-packages/telegram/ext/_basehandler.py", line 157, in handle_update
    return await self.callback(update, context)
           ^^^^^^^^^^^^^^^^^^^^^^^^^^^^^^^^^^^^
  File "/root/jupyter-env/project_outline/client_bot/keyboards/my_stats.py", line 66, in handle_my_stats_callback
    await query.message.reply_text(f"📦 <b>Суммарный трафик:</b> {total_traffic_mb:.2f} MB", parse_mode="HTML")
  File "/root/jupyter-env/lib/python3.12/site-packages/telegram/_message.py", line 1094, in reply_text
    return await self.get_bot().send_message(
           ^^^^^^^^^^^^^^^^^^^^^^^^^^^^^^^^^^
  File "/root/jupyter-env/lib/python3.12/site-packages/telegram/ext/_extbot.py", line 2624, in send_message
    return await super().send_message(
           ^^^^^^^^^^^^^^^^^^^^^^^^^^^
  File "/root/jupyter-env/lib/python3.12/site-packages/telegram/_bot.py", line 525, in decorator
    result = await func(self, *args, **kwargs)  # skipcq: PYL-E1102
             ^^^^^^^^^^^^^^^^^^^^^^^^^^^^^^^^^
  File "/root/jupyter-env/lib/python3.12/site-packages/telegram/_bot.py", line 846, in send_message
    return await self._send_message(
           ^^^^^^^^^^^^^^^^^^^^^^^^^
  File "/root/jupyter-env/lib/python3.12/site-packages/telegram/ext/_extbot.py", line 522, in _send_message
    result = await super()._send_message(
             ^^^^^^^^^^^^^^^^^^^^^^^^^^^^
  File "/root/jupyter-env/lib/python3.12/site-packages/telegram/_bot.py", line 703, in _send_message
    result = await self._post(
             ^^^^^^^^^^^^^^^^^
  File "/root/jupyter-env/lib/python3.12/site-packages/telegram/_bot.py", line 613, in _post
    return await self._do_post(
           ^^^^^^^^^^^^^^^^^^^^
  File "/root/jupyter-env/lib/python3.12/site-packages/telegram/ext/_extbot.py", line 340, in _do_post
    return await super()._do_post(
           ^^^^^^^^^^^^^^^^^^^^^^^
  File "/root/jupyter-env/lib/python3.12/site-packages/telegram/_bot.py", line 641, in _do_post
    return await request.post(
           ^^^^^^^^^^^^^^^^^^^
  File "/root/jupyter-env/lib/python3.12/site-packages/telegram/request/_baserequest.py", line 200, in post
    result = await self._request_wrapper(
             ^^^^^^^^^^^^^^^^^^^^^^^^^^^^
  File "/root/jupyter-env/lib/python3.12/site-packages/telegram/request/_baserequest.py", line 340, in _request_wrapper
    raise exc
  File "/root/jupyter-env/lib/python3.12/site-packages/telegram/request/_baserequest.py", line 330, in _request_wrapper
    code, payload = await self.do_request(
                    ^^^^^^^^^^^^^^^^^^^^^^
  File "/root/jupyter-env/lib/python3.12/site-packages/telegram/request/_httpxrequest.py", line 292, in do_request
    raise NetworkError(f"httpx.{err.__class__.__name__}: {err}") from err
telegram.error.NetworkError: httpx.ReadError: 
Error while getting Updates: httpx.ReadError: 
No error handlers are registered, logging exception.
Traceback (most recent call last):
  File "/root/jupyter-env/lib/python3.12/site-packages/httpx/_transports/default.py", line 66, in map_httpcore_exceptions
    yield
  File "/root/jupyter-env/lib/python3.12/site-packages/httpx/_transports/default.py", line 366, in handle_async_request
    resp = await self._pool.handle_async_request(req)
           ^^^^^^^^^^^^^^^^^^^^^^^^^^^^^^^^^^^^^^^^^^
  File "/root/jupyter-env/lib/python3.12/site-packages/httpcore/_async/connection_pool.py", line 256, in handle_async_request
    raise exc from None
  File "/root/jupyter-env/lib/python3.12/site-packages/httpcore/_async/connection_pool.py", line 236, in handle_async_request
    response = await connection.handle_async_request(
               ^^^^^^^^^^^^^^^^^^^^^^^^^^^^^^^^^^^^^^
  File "/root/jupyter-env/lib/python3.12/site-packages/httpcore/_async/connection.py", line 103, in handle_async_request
    return await self._connection.handle_async_request(request)
           ^^^^^^^^^^^^^^^^^^^^^^^^^^^^^^^^^^^^^^^^^^^^^^^^^^^^
  File "/root/jupyter-env/lib/python3.12/site-packages/httpcore/_async/http11.py", line 136, in handle_async_request
    raise exc
  File "/root/jupyter-env/lib/python3.12/site-packages/httpcore/_async/http11.py", line 106, in handle_async_request
    ) = await self._receive_response_headers(**kwargs)
        ^^^^^^^^^^^^^^^^^^^^^^^^^^^^^^^^^^^^^^^^^^^^^^
  File "/root/jupyter-env/lib/python3.12/site-packages/httpcore/_async/http11.py", line 177, in _receive_response_headers
    event = await self._receive_event(timeout=timeout)
            ^^^^^^^^^^^^^^^^^^^^^^^^^^^^^^^^^^^^^^^^^^
  File "/root/jupyter-env/lib/python3.12/site-packages/httpcore/_async/http11.py", line 217, in _receive_event
    data = await self._network_stream.read(
           ^^^^^^^^^^^^^^^^^^^^^^^^^^^^^^^^
  File "/root/jupyter-env/lib/python3.12/site-packages/httpcore/_backends/anyio.py", line 32, in read
    with map_exceptions(exc_map):
  File "/usr/lib/python3.12/contextlib.py", line 158, in __exit__
    self.gen.throw(value)
  File "/root/jupyter-env/lib/python3.12/site-packages/httpcore/_exceptions.py", line 14, in map_exceptions
    raise to_exc(exc) from exc
httpcore.ReadError

The above exception was the direct cause of the following exception:

Traceback (most recent call last):
  File "/root/jupyter-env/lib/python3.12/site-packages/telegram/request/_httpxrequest.py", line 268, in do_request
    res = await self._client.request(
          ^^^^^^^^^^^^^^^^^^^^^^^^^^^
  File "/root/jupyter-env/lib/python3.12/site-packages/httpx/_client.py", line 1530, in request
    return await self.send(request, auth=auth, follow_redirects=follow_redirects)
           ^^^^^^^^^^^^^^^^^^^^^^^^^^^^^^^^^^^^^^^^^^^^^^^^^^^^^^^^^^^^^^^^^^^^^^
  File "/root/jupyter-env/lib/python3.12/site-packages/httpx/_client.py", line 1617, in send
    response = await self._send_handling_auth(
               ^^^^^^^^^^^^^^^^^^^^^^^^^^^^^^^
  File "/root/jupyter-env/lib/python3.12/site-packages/httpx/_client.py", line 1645, in _send_handling_auth
    response = await self._send_handling_redirects(
               ^^^^^^^^^^^^^^^^^^^^^^^^^^^^^^^^^^^^
  File "/root/jupyter-env/lib/python3.12/site-packages/httpx/_client.py", line 1682, in _send_handling_redirects
    response = await self._send_single_request(request)
               ^^^^^^^^^^^^^^^^^^^^^^^^^^^^^^^^^^^^^^^^
  File "/root/jupyter-env/lib/python3.12/site-packages/httpx/_client.py", line 1719, in _send_single_request
    response = await transport.handle_async_request(request)
               ^^^^^^^^^^^^^^^^^^^^^^^^^^^^^^^^^^^^^^^^^^^^^
  File "/root/jupyter-env/lib/python3.12/site-packages/httpx/_transports/default.py", line 365, in handle_async_request
    with map_httpcore_exceptions():
  File "/usr/lib/python3.12/contextlib.py", line 158, in __exit__
    self.gen.throw(value)
  File "/root/jupyter-env/lib/python3.12/site-packages/httpx/_transports/default.py", line 83, in map_httpcore_exceptions
    raise mapped_exc(message) from exc
httpx.ReadError

The above exception was the direct cause of the following exception:

Traceback (most recent call last):
  File "/root/jupyter-env/lib/python3.12/site-packages/telegram/ext/_updater.py", line 688, in _network_loop_retry
    if not await action_cb():
           ^^^^^^^^^^^^^^^^^
  File "/root/jupyter-env/lib/python3.12/site-packages/telegram/ext/_updater.py", line 384, in polling_action_cb
    raise exc
  File "/root/jupyter-env/lib/python3.12/site-packages/telegram/ext/_updater.py", line 373, in polling_action_cb
    updates = await self.bot.get_updates(
              ^^^^^^^^^^^^^^^^^^^^^^^^^^^
  File "/root/jupyter-env/lib/python3.12/site-packages/telegram/ext/_extbot.py", line 558, in get_updates
    updates = await super().get_updates(
              ^^^^^^^^^^^^^^^^^^^^^^^^^^
  File "/root/jupyter-env/lib/python3.12/site-packages/telegram/_bot.py", line 525, in decorator
    result = await func(self, *args, **kwargs)  # skipcq: PYL-E1102
             ^^^^^^^^^^^^^^^^^^^^^^^^^^^^^^^^^
  File "/root/jupyter-env/lib/python3.12/site-packages/telegram/_bot.py", line 3584, in get_updates
    await self._post(
  File "/root/jupyter-env/lib/python3.12/site-packages/telegram/_bot.py", line 613, in _post
    return await self._do_post(
           ^^^^^^^^^^^^^^^^^^^^
  File "/root/jupyter-env/lib/python3.12/site-packages/telegram/ext/_extbot.py", line 340, in _do_post
    return await super()._do_post(
           ^^^^^^^^^^^^^^^^^^^^^^^
  File "/root/jupyter-env/lib/python3.12/site-packages/telegram/_bot.py", line 641, in _do_post
    return await request.post(
           ^^^^^^^^^^^^^^^^^^^
  File "/root/jupyter-env/lib/python3.12/site-packages/telegram/request/_baserequest.py", line 200, in post
    result = await self._request_wrapper(
             ^^^^^^^^^^^^^^^^^^^^^^^^^^^^
  File "/root/jupyter-env/lib/python3.12/site-packages/telegram/request/_baserequest.py", line 340, in _request_wrapper
    raise exc
  File "/root/jupyter-env/lib/python3.12/site-packages/telegram/request/_baserequest.py", line 330, in _request_wrapper
    code, payload = await self.do_request(
                    ^^^^^^^^^^^^^^^^^^^^^^
  File "/root/jupyter-env/lib/python3.12/site-packages/telegram/request/_httpxrequest.py", line 292, in do_request
    raise NetworkError(f"httpx.{err.__class__.__name__}: {err}") from err
telegram.error.NetworkError: httpx.ReadError: 
Error while getting Updates: httpx.ReadError: 
No error handlers are registered, logging exception.
Traceback (most recent call last):
  File "/root/jupyter-env/lib/python3.12/site-packages/httpx/_transports/default.py", line 66, in map_httpcore_exceptions
    yield
  File "/root/jupyter-env/lib/python3.12/site-packages/httpx/_transports/default.py", line 366, in handle_async_request
    resp = await self._pool.handle_async_request(req)
           ^^^^^^^^^^^^^^^^^^^^^^^^^^^^^^^^^^^^^^^^^^
  File "/root/jupyter-env/lib/python3.12/site-packages/httpcore/_async/connection_pool.py", line 256, in handle_async_request
    raise exc from None
  File "/root/jupyter-env/lib/python3.12/site-packages/httpcore/_async/connection_pool.py", line 236, in handle_async_request
    response = await connection.handle_async_request(
               ^^^^^^^^^^^^^^^^^^^^^^^^^^^^^^^^^^^^^^
  File "/root/jupyter-env/lib/python3.12/site-packages/httpcore/_async/connection.py", line 103, in handle_async_request
    return await self._connection.handle_async_request(request)
           ^^^^^^^^^^^^^^^^^^^^^^^^^^^^^^^^^^^^^^^^^^^^^^^^^^^^
  File "/root/jupyter-env/lib/python3.12/site-packages/httpcore/_async/http11.py", line 136, in handle_async_request
    raise exc
  File "/root/jupyter-env/lib/python3.12/site-packages/httpcore/_async/http11.py", line 106, in handle_async_request
    ) = await self._receive_response_headers(**kwargs)
        ^^^^^^^^^^^^^^^^^^^^^^^^^^^^^^^^^^^^^^^^^^^^^^
  File "/root/jupyter-env/lib/python3.12/site-packages/httpcore/_async/http11.py", line 177, in _receive_response_headers
    event = await self._receive_event(timeout=timeout)
            ^^^^^^^^^^^^^^^^^^^^^^^^^^^^^^^^^^^^^^^^^^
  File "/root/jupyter-env/lib/python3.12/site-packages/httpcore/_async/http11.py", line 217, in _receive_event
    data = await self._network_stream.read(
           ^^^^^^^^^^^^^^^^^^^^^^^^^^^^^^^^
  File "/root/jupyter-env/lib/python3.12/site-packages/httpcore/_backends/anyio.py", line 32, in read
    with map_exceptions(exc_map):
  File "/usr/lib/python3.12/contextlib.py", line 158, in __exit__
    self.gen.throw(value)
  File "/root/jupyter-env/lib/python3.12/site-packages/httpcore/_exceptions.py", line 14, in map_exceptions
    raise to_exc(exc) from exc
httpcore.ReadError

The above exception was the direct cause of the following exception:

Traceback (most recent call last):
  File "/root/jupyter-env/lib/python3.12/site-packages/telegram/request/_httpxrequest.py", line 268, in do_request
    res = await self._client.request(
          ^^^^^^^^^^^^^^^^^^^^^^^^^^^
  File "/root/jupyter-env/lib/python3.12/site-packages/httpx/_client.py", line 1530, in request
    return await self.send(request, auth=auth, follow_redirects=follow_redirects)
           ^^^^^^^^^^^^^^^^^^^^^^^^^^^^^^^^^^^^^^^^^^^^^^^^^^^^^^^^^^^^^^^^^^^^^^
  File "/root/jupyter-env/lib/python3.12/site-packages/httpx/_client.py", line 1617, in send
    response = await self._send_handling_auth(
               ^^^^^^^^^^^^^^^^^^^^^^^^^^^^^^^
  File "/root/jupyter-env/lib/python3.12/site-packages/httpx/_client.py", line 1645, in _send_handling_auth
    response = await self._send_handling_redirects(
               ^^^^^^^^^^^^^^^^^^^^^^^^^^^^^^^^^^^^
  File "/root/jupyter-env/lib/python3.12/site-packages/httpx/_client.py", line 1682, in _send_handling_redirects
    response = await self._send_single_request(request)
               ^^^^^^^^^^^^^^^^^^^^^^^^^^^^^^^^^^^^^^^^
  File "/root/jupyter-env/lib/python3.12/site-packages/httpx/_client.py", line 1719, in _send_single_request
    response = await transport.handle_async_request(request)
               ^^^^^^^^^^^^^^^^^^^^^^^^^^^^^^^^^^^^^^^^^^^^^
  File "/root/jupyter-env/lib/python3.12/site-packages/httpx/_transports/default.py", line 365, in handle_async_request
    with map_httpcore_exceptions():
  File "/usr/lib/python3.12/contextlib.py", line 158, in __exit__
    self.gen.throw(value)
  File "/root/jupyter-env/lib/python3.12/site-packages/httpx/_transports/default.py", line 83, in map_httpcore_exceptions
    raise mapped_exc(message) from exc
httpx.ReadError

The above exception was the direct cause of the following exception:

Traceback (most recent call last):
  File "/root/jupyter-env/lib/python3.12/site-packages/telegram/ext/_updater.py", line 688, in _network_loop_retry
    if not await action_cb():
           ^^^^^^^^^^^^^^^^^
  File "/root/jupyter-env/lib/python3.12/site-packages/telegram/ext/_updater.py", line 384, in polling_action_cb
    raise exc
  File "/root/jupyter-env/lib/python3.12/site-packages/telegram/ext/_updater.py", line 373, in polling_action_cb
    updates = await self.bot.get_updates(
              ^^^^^^^^^^^^^^^^^^^^^^^^^^^
  File "/root/jupyter-env/lib/python3.12/site-packages/telegram/ext/_extbot.py", line 558, in get_updates
    updates = await super().get_updates(
              ^^^^^^^^^^^^^^^^^^^^^^^^^^
  File "/root/jupyter-env/lib/python3.12/site-packages/telegram/_bot.py", line 525, in decorator
    result = await func(self, *args, **kwargs)  # skipcq: PYL-E1102
             ^^^^^^^^^^^^^^^^^^^^^^^^^^^^^^^^^
  File "/root/jupyter-env/lib/python3.12/site-packages/telegram/_bot.py", line 3584, in get_updates
    await self._post(
  File "/root/jupyter-env/lib/python3.12/site-packages/telegram/_bot.py", line 613, in _post
    return await self._do_post(
           ^^^^^^^^^^^^^^^^^^^^
  File "/root/jupyter-env/lib/python3.12/site-packages/telegram/ext/_extbot.py", line 340, in _do_post
    return await super()._do_post(
           ^^^^^^^^^^^^^^^^^^^^^^^
  File "/root/jupyter-env/lib/python3.12/site-packages/telegram/_bot.py", line 641, in _do_post
    return await request.post(
           ^^^^^^^^^^^^^^^^^^^
  File "/root/jupyter-env/lib/python3.12/site-packages/telegram/request/_baserequest.py", line 200, in post
    result = await self._request_wrapper(
             ^^^^^^^^^^^^^^^^^^^^^^^^^^^^
  File "/root/jupyter-env/lib/python3.12/site-packages/telegram/request/_baserequest.py", line 340, in _request_wrapper
    raise exc
  File "/root/jupyter-env/lib/python3.12/site-packages/telegram/request/_baserequest.py", line 330, in _request_wrapper
    code, payload = await self.do_request(
                    ^^^^^^^^^^^^^^^^^^^^^^
  File "/root/jupyter-env/lib/python3.12/site-packages/telegram/request/_httpxrequest.py", line 292, in do_request
    raise NetworkError(f"httpx.{err.__class__.__name__}: {err}") from err
telegram.error.NetworkError: httpx.ReadError: 
Error while getting Updates: httpx.ReadError: 
No error handlers are registered, logging exception.
Traceback (most recent call last):
  File "/root/jupyter-env/lib/python3.12/site-packages/httpx/_transports/default.py", line 66, in map_httpcore_exceptions
    yield
  File "/root/jupyter-env/lib/python3.12/site-packages/httpx/_transports/default.py", line 366, in handle_async_request
    resp = await self._pool.handle_async_request(req)
           ^^^^^^^^^^^^^^^^^^^^^^^^^^^^^^^^^^^^^^^^^^
  File "/root/jupyter-env/lib/python3.12/site-packages/httpcore/_async/connection_pool.py", line 256, in handle_async_request
    raise exc from None
  File "/root/jupyter-env/lib/python3.12/site-packages/httpcore/_async/connection_pool.py", line 236, in handle_async_request
    response = await connection.handle_async_request(
               ^^^^^^^^^^^^^^^^^^^^^^^^^^^^^^^^^^^^^^
  File "/root/jupyter-env/lib/python3.12/site-packages/httpcore/_async/connection.py", line 103, in handle_async_request
    return await self._connection.handle_async_request(request)
           ^^^^^^^^^^^^^^^^^^^^^^^^^^^^^^^^^^^^^^^^^^^^^^^^^^^^
  File "/root/jupyter-env/lib/python3.12/site-packages/httpcore/_async/http11.py", line 136, in handle_async_request
    raise exc
  File "/root/jupyter-env/lib/python3.12/site-packages/httpcore/_async/http11.py", line 106, in handle_async_request
    ) = await self._receive_response_headers(**kwargs)
        ^^^^^^^^^^^^^^^^^^^^^^^^^^^^^^^^^^^^^^^^^^^^^^
  File "/root/jupyter-env/lib/python3.12/site-packages/httpcore/_async/http11.py", line 177, in _receive_response_headers
    event = await self._receive_event(timeout=timeout)
            ^^^^^^^^^^^^^^^^^^^^^^^^^^^^^^^^^^^^^^^^^^
  File "/root/jupyter-env/lib/python3.12/site-packages/httpcore/_async/http11.py", line 217, in _receive_event
    data = await self._network_stream.read(
           ^^^^^^^^^^^^^^^^^^^^^^^^^^^^^^^^
  File "/root/jupyter-env/lib/python3.12/site-packages/httpcore/_backends/anyio.py", line 32, in read
    with map_exceptions(exc_map):
  File "/usr/lib/python3.12/contextlib.py", line 158, in __exit__
    self.gen.throw(value)
  File "/root/jupyter-env/lib/python3.12/site-packages/httpcore/_exceptions.py", line 14, in map_exceptions
    raise to_exc(exc) from exc
httpcore.ReadError

The above exception was the direct cause of the following exception:

Traceback (most recent call last):
  File "/root/jupyter-env/lib/python3.12/site-packages/telegram/request/_httpxrequest.py", line 268, in do_request
    res = await self._client.request(
          ^^^^^^^^^^^^^^^^^^^^^^^^^^^
  File "/root/jupyter-env/lib/python3.12/site-packages/httpx/_client.py", line 1530, in request
    return await self.send(request, auth=auth, follow_redirects=follow_redirects)
           ^^^^^^^^^^^^^^^^^^^^^^^^^^^^^^^^^^^^^^^^^^^^^^^^^^^^^^^^^^^^^^^^^^^^^^
  File "/root/jupyter-env/lib/python3.12/site-packages/httpx/_client.py", line 1617, in send
    response = await self._send_handling_auth(
               ^^^^^^^^^^^^^^^^^^^^^^^^^^^^^^^
  File "/root/jupyter-env/lib/python3.12/site-packages/httpx/_client.py", line 1645, in _send_handling_auth
    response = await self._send_handling_redirects(
               ^^^^^^^^^^^^^^^^^^^^^^^^^^^^^^^^^^^^
  File "/root/jupyter-env/lib/python3.12/site-packages/httpx/_client.py", line 1682, in _send_handling_redirects
    response = await self._send_single_request(request)
               ^^^^^^^^^^^^^^^^^^^^^^^^^^^^^^^^^^^^^^^^
  File "/root/jupyter-env/lib/python3.12/site-packages/httpx/_client.py", line 1719, in _send_single_request
    response = await transport.handle_async_request(request)
               ^^^^^^^^^^^^^^^^^^^^^^^^^^^^^^^^^^^^^^^^^^^^^
  File "/root/jupyter-env/lib/python3.12/site-packages/httpx/_transports/default.py", line 365, in handle_async_request
    with map_httpcore_exceptions():
  File "/usr/lib/python3.12/contextlib.py", line 158, in __exit__
    self.gen.throw(value)
  File "/root/jupyter-env/lib/python3.12/site-packages/httpx/_transports/default.py", line 83, in map_httpcore_exceptions
    raise mapped_exc(message) from exc
httpx.ReadError

The above exception was the direct cause of the following exception:

Traceback (most recent call last):
  File "/root/jupyter-env/lib/python3.12/site-packages/telegram/ext/_updater.py", line 688, in _network_loop_retry
    if not await action_cb():
           ^^^^^^^^^^^^^^^^^
  File "/root/jupyter-env/lib/python3.12/site-packages/telegram/ext/_updater.py", line 384, in polling_action_cb
    raise exc
  File "/root/jupyter-env/lib/python3.12/site-packages/telegram/ext/_updater.py", line 373, in polling_action_cb
    updates = await self.bot.get_updates(
              ^^^^^^^^^^^^^^^^^^^^^^^^^^^
  File "/root/jupyter-env/lib/python3.12/site-packages/telegram/ext/_extbot.py", line 558, in get_updates
    updates = await super().get_updates(
              ^^^^^^^^^^^^^^^^^^^^^^^^^^
  File "/root/jupyter-env/lib/python3.12/site-packages/telegram/_bot.py", line 525, in decorator
    result = await func(self, *args, **kwargs)  # skipcq: PYL-E1102
             ^^^^^^^^^^^^^^^^^^^^^^^^^^^^^^^^^
  File "/root/jupyter-env/lib/python3.12/site-packages/telegram/_bot.py", line 3584, in get_updates
    await self._post(
  File "/root/jupyter-env/lib/python3.12/site-packages/telegram/_bot.py", line 613, in _post
    return await self._do_post(
           ^^^^^^^^^^^^^^^^^^^^
  File "/root/jupyter-env/lib/python3.12/site-packages/telegram/ext/_extbot.py", line 340, in _do_post
    return await super()._do_post(
           ^^^^^^^^^^^^^^^^^^^^^^^
  File "/root/jupyter-env/lib/python3.12/site-packages/telegram/_bot.py", line 641, in _do_post
    return await request.post(
           ^^^^^^^^^^^^^^^^^^^
  File "/root/jupyter-env/lib/python3.12/site-packages/telegram/request/_baserequest.py", line 200, in post
    result = await self._request_wrapper(
             ^^^^^^^^^^^^^^^^^^^^^^^^^^^^
  File "/root/jupyter-env/lib/python3.12/site-packages/telegram/request/_baserequest.py", line 340, in _request_wrapper
    raise exc
  File "/root/jupyter-env/lib/python3.12/site-packages/telegram/request/_baserequest.py", line 330, in _request_wrapper
    code, payload = await self.do_request(
                    ^^^^^^^^^^^^^^^^^^^^^^
  File "/root/jupyter-env/lib/python3.12/site-packages/telegram/request/_httpxrequest.py", line 292, in do_request
    raise NetworkError(f"httpx.{err.__class__.__name__}: {err}") from err
telegram.error.NetworkError: httpx.ReadError: 
Error while getting Updates: httpx.ReadError: 
No error handlers are registered, logging exception.
Traceback (most recent call last):
  File "/root/jupyter-env/lib/python3.12/site-packages/httpx/_transports/default.py", line 66, in map_httpcore_exceptions
    yield
  File "/root/jupyter-env/lib/python3.12/site-packages/httpx/_transports/default.py", line 366, in handle_async_request
    resp = await self._pool.handle_async_request(req)
           ^^^^^^^^^^^^^^^^^^^^^^^^^^^^^^^^^^^^^^^^^^
  File "/root/jupyter-env/lib/python3.12/site-packages/httpcore/_async/connection_pool.py", line 256, in handle_async_request
    raise exc from None
  File "/root/jupyter-env/lib/python3.12/site-packages/httpcore/_async/connection_pool.py", line 236, in handle_async_request
    response = await connection.handle_async_request(
               ^^^^^^^^^^^^^^^^^^^^^^^^^^^^^^^^^^^^^^
  File "/root/jupyter-env/lib/python3.12/site-packages/httpcore/_async/connection.py", line 103, in handle_async_request
    return await self._connection.handle_async_request(request)
           ^^^^^^^^^^^^^^^^^^^^^^^^^^^^^^^^^^^^^^^^^^^^^^^^^^^^
  File "/root/jupyter-env/lib/python3.12/site-packages/httpcore/_async/http11.py", line 136, in handle_async_request
    raise exc
  File "/root/jupyter-env/lib/python3.12/site-packages/httpcore/_async/http11.py", line 106, in handle_async_request
    ) = await self._receive_response_headers(**kwargs)
        ^^^^^^^^^^^^^^^^^^^^^^^^^^^^^^^^^^^^^^^^^^^^^^
  File "/root/jupyter-env/lib/python3.12/site-packages/httpcore/_async/http11.py", line 177, in _receive_response_headers
    event = await self._receive_event(timeout=timeout)
            ^^^^^^^^^^^^^^^^^^^^^^^^^^^^^^^^^^^^^^^^^^
  File "/root/jupyter-env/lib/python3.12/site-packages/httpcore/_async/http11.py", line 217, in _receive_event
    data = await self._network_stream.read(
           ^^^^^^^^^^^^^^^^^^^^^^^^^^^^^^^^
  File "/root/jupyter-env/lib/python3.12/site-packages/httpcore/_backends/anyio.py", line 32, in read
    with map_exceptions(exc_map):
  File "/usr/lib/python3.12/contextlib.py", line 158, in __exit__
    self.gen.throw(value)
  File "/root/jupyter-env/lib/python3.12/site-packages/httpcore/_exceptions.py", line 14, in map_exceptions
    raise to_exc(exc) from exc
httpcore.ReadError

The above exception was the direct cause of the following exception:

Traceback (most recent call last):
  File "/root/jupyter-env/lib/python3.12/site-packages/telegram/request/_httpxrequest.py", line 268, in do_request
    res = await self._client.request(
          ^^^^^^^^^^^^^^^^^^^^^^^^^^^
  File "/root/jupyter-env/lib/python3.12/site-packages/httpx/_client.py", line 1530, in request
    return await self.send(request, auth=auth, follow_redirects=follow_redirects)
           ^^^^^^^^^^^^^^^^^^^^^^^^^^^^^^^^^^^^^^^^^^^^^^^^^^^^^^^^^^^^^^^^^^^^^^
  File "/root/jupyter-env/lib/python3.12/site-packages/httpx/_client.py", line 1617, in send
    response = await self._send_handling_auth(
               ^^^^^^^^^^^^^^^^^^^^^^^^^^^^^^^
  File "/root/jupyter-env/lib/python3.12/site-packages/httpx/_client.py", line 1645, in _send_handling_auth
    response = await self._send_handling_redirects(
               ^^^^^^^^^^^^^^^^^^^^^^^^^^^^^^^^^^^^
  File "/root/jupyter-env/lib/python3.12/site-packages/httpx/_client.py", line 1682, in _send_handling_redirects
    response = await self._send_single_request(request)
               ^^^^^^^^^^^^^^^^^^^^^^^^^^^^^^^^^^^^^^^^
  File "/root/jupyter-env/lib/python3.12/site-packages/httpx/_client.py", line 1719, in _send_single_request
    response = await transport.handle_async_request(request)
               ^^^^^^^^^^^^^^^^^^^^^^^^^^^^^^^^^^^^^^^^^^^^^
  File "/root/jupyter-env/lib/python3.12/site-packages/httpx/_transports/default.py", line 365, in handle_async_request
    with map_httpcore_exceptions():
  File "/usr/lib/python3.12/contextlib.py", line 158, in __exit__
    self.gen.throw(value)
  File "/root/jupyter-env/lib/python3.12/site-packages/httpx/_transports/default.py", line 83, in map_httpcore_exceptions
    raise mapped_exc(message) from exc
httpx.ReadError

The above exception was the direct cause of the following exception:

Traceback (most recent call last):
  File "/root/jupyter-env/lib/python3.12/site-packages/telegram/ext/_updater.py", line 688, in _network_loop_retry
    if not await action_cb():
           ^^^^^^^^^^^^^^^^^
  File "/root/jupyter-env/lib/python3.12/site-packages/telegram/ext/_updater.py", line 384, in polling_action_cb
    raise exc
  File "/root/jupyter-env/lib/python3.12/site-packages/telegram/ext/_updater.py", line 373, in polling_action_cb
    updates = await self.bot.get_updates(
              ^^^^^^^^^^^^^^^^^^^^^^^^^^^
  File "/root/jupyter-env/lib/python3.12/site-packages/telegram/ext/_extbot.py", line 558, in get_updates
    updates = await super().get_updates(
              ^^^^^^^^^^^^^^^^^^^^^^^^^^
  File "/root/jupyter-env/lib/python3.12/site-packages/telegram/_bot.py", line 525, in decorator
    result = await func(self, *args, **kwargs)  # skipcq: PYL-E1102
             ^^^^^^^^^^^^^^^^^^^^^^^^^^^^^^^^^
  File "/root/jupyter-env/lib/python3.12/site-packages/telegram/_bot.py", line 3584, in get_updates
    await self._post(
  File "/root/jupyter-env/lib/python3.12/site-packages/telegram/_bot.py", line 613, in _post
    return await self._do_post(
           ^^^^^^^^^^^^^^^^^^^^
  File "/root/jupyter-env/lib/python3.12/site-packages/telegram/ext/_extbot.py", line 340, in _do_post
    return await super()._do_post(
           ^^^^^^^^^^^^^^^^^^^^^^^
  File "/root/jupyter-env/lib/python3.12/site-packages/telegram/_bot.py", line 641, in _do_post
    return await request.post(
           ^^^^^^^^^^^^^^^^^^^
  File "/root/jupyter-env/lib/python3.12/site-packages/telegram/request/_baserequest.py", line 200, in post
    result = await self._request_wrapper(
             ^^^^^^^^^^^^^^^^^^^^^^^^^^^^
  File "/root/jupyter-env/lib/python3.12/site-packages/telegram/request/_baserequest.py", line 340, in _request_wrapper
    raise exc
  File "/root/jupyter-env/lib/python3.12/site-packages/telegram/request/_baserequest.py", line 330, in _request_wrapper
    code, payload = await self.do_request(
                    ^^^^^^^^^^^^^^^^^^^^^^
  File "/root/jupyter-env/lib/python3.12/site-packages/telegram/request/_httpxrequest.py", line 292, in do_request
    raise NetworkError(f"httpx.{err.__class__.__name__}: {err}") from err
telegram.error.NetworkError: httpx.ReadError: 
Error while getting Updates: httpx.ReadError: 
No error handlers are registered, logging exception.
Traceback (most recent call last):
  File "/root/jupyter-env/lib/python3.12/site-packages/httpx/_transports/default.py", line 66, in map_httpcore_exceptions
    yield
  File "/root/jupyter-env/lib/python3.12/site-packages/httpx/_transports/default.py", line 366, in handle_async_request
    resp = await self._pool.handle_async_request(req)
           ^^^^^^^^^^^^^^^^^^^^^^^^^^^^^^^^^^^^^^^^^^
  File "/root/jupyter-env/lib/python3.12/site-packages/httpcore/_async/connection_pool.py", line 256, in handle_async_request
    raise exc from None
  File "/root/jupyter-env/lib/python3.12/site-packages/httpcore/_async/connection_pool.py", line 236, in handle_async_request
    response = await connection.handle_async_request(
               ^^^^^^^^^^^^^^^^^^^^^^^^^^^^^^^^^^^^^^
  File "/root/jupyter-env/lib/python3.12/site-packages/httpcore/_async/connection.py", line 103, in handle_async_request
    return await self._connection.handle_async_request(request)
           ^^^^^^^^^^^^^^^^^^^^^^^^^^^^^^^^^^^^^^^^^^^^^^^^^^^^
  File "/root/jupyter-env/lib/python3.12/site-packages/httpcore/_async/http11.py", line 136, in handle_async_request
    raise exc
  File "/root/jupyter-env/lib/python3.12/site-packages/httpcore/_async/http11.py", line 106, in handle_async_request
    ) = await self._receive_response_headers(**kwargs)
        ^^^^^^^^^^^^^^^^^^^^^^^^^^^^^^^^^^^^^^^^^^^^^^
  File "/root/jupyter-env/lib/python3.12/site-packages/httpcore/_async/http11.py", line 177, in _receive_response_headers
    event = await self._receive_event(timeout=timeout)
            ^^^^^^^^^^^^^^^^^^^^^^^^^^^^^^^^^^^^^^^^^^
  File "/root/jupyter-env/lib/python3.12/site-packages/httpcore/_async/http11.py", line 217, in _receive_event
    data = await self._network_stream.read(
           ^^^^^^^^^^^^^^^^^^^^^^^^^^^^^^^^
  File "/root/jupyter-env/lib/python3.12/site-packages/httpcore/_backends/anyio.py", line 32, in read
    with map_exceptions(exc_map):
  File "/usr/lib/python3.12/contextlib.py", line 158, in __exit__
    self.gen.throw(value)
  File "/root/jupyter-env/lib/python3.12/site-packages/httpcore/_exceptions.py", line 14, in map_exceptions
    raise to_exc(exc) from exc
httpcore.ReadError

The above exception was the direct cause of the following exception:

Traceback (most recent call last):
  File "/root/jupyter-env/lib/python3.12/site-packages/telegram/request/_httpxrequest.py", line 268, in do_request
    res = await self._client.request(
          ^^^^^^^^^^^^^^^^^^^^^^^^^^^
  File "/root/jupyter-env/lib/python3.12/site-packages/httpx/_client.py", line 1530, in request
    return await self.send(request, auth=auth, follow_redirects=follow_redirects)
           ^^^^^^^^^^^^^^^^^^^^^^^^^^^^^^^^^^^^^^^^^^^^^^^^^^^^^^^^^^^^^^^^^^^^^^
  File "/root/jupyter-env/lib/python3.12/site-packages/httpx/_client.py", line 1617, in send
    response = await self._send_handling_auth(
               ^^^^^^^^^^^^^^^^^^^^^^^^^^^^^^^
  File "/root/jupyter-env/lib/python3.12/site-packages/httpx/_client.py", line 1645, in _send_handling_auth
    response = await self._send_handling_redirects(
               ^^^^^^^^^^^^^^^^^^^^^^^^^^^^^^^^^^^^
  File "/root/jupyter-env/lib/python3.12/site-packages/httpx/_client.py", line 1682, in _send_handling_redirects
    response = await self._send_single_request(request)
               ^^^^^^^^^^^^^^^^^^^^^^^^^^^^^^^^^^^^^^^^
  File "/root/jupyter-env/lib/python3.12/site-packages/httpx/_client.py", line 1719, in _send_single_request
    response = await transport.handle_async_request(request)
               ^^^^^^^^^^^^^^^^^^^^^^^^^^^^^^^^^^^^^^^^^^^^^
  File "/root/jupyter-env/lib/python3.12/site-packages/httpx/_transports/default.py", line 365, in handle_async_request
    with map_httpcore_exceptions():
  File "/usr/lib/python3.12/contextlib.py", line 158, in __exit__
    self.gen.throw(value)
  File "/root/jupyter-env/lib/python3.12/site-packages/httpx/_transports/default.py", line 83, in map_httpcore_exceptions
    raise mapped_exc(message) from exc
httpx.ReadError

The above exception was the direct cause of the following exception:

Traceback (most recent call last):
  File "/root/jupyter-env/lib/python3.12/site-packages/telegram/ext/_updater.py", line 688, in _network_loop_retry
    if not await action_cb():
           ^^^^^^^^^^^^^^^^^
  File "/root/jupyter-env/lib/python3.12/site-packages/telegram/ext/_updater.py", line 384, in polling_action_cb
    raise exc
  File "/root/jupyter-env/lib/python3.12/site-packages/telegram/ext/_updater.py", line 373, in polling_action_cb
    updates = await self.bot.get_updates(
              ^^^^^^^^^^^^^^^^^^^^^^^^^^^
  File "/root/jupyter-env/lib/python3.12/site-packages/telegram/ext/_extbot.py", line 558, in get_updates
    updates = await super().get_updates(
              ^^^^^^^^^^^^^^^^^^^^^^^^^^
  File "/root/jupyter-env/lib/python3.12/site-packages/telegram/_bot.py", line 525, in decorator
    result = await func(self, *args, **kwargs)  # skipcq: PYL-E1102
             ^^^^^^^^^^^^^^^^^^^^^^^^^^^^^^^^^
  File "/root/jupyter-env/lib/python3.12/site-packages/telegram/_bot.py", line 3584, in get_updates
    await self._post(
  File "/root/jupyter-env/lib/python3.12/site-packages/telegram/_bot.py", line 613, in _post
    return await self._do_post(
           ^^^^^^^^^^^^^^^^^^^^
  File "/root/jupyter-env/lib/python3.12/site-packages/telegram/ext/_extbot.py", line 340, in _do_post
    return await super()._do_post(
           ^^^^^^^^^^^^^^^^^^^^^^^
  File "/root/jupyter-env/lib/python3.12/site-packages/telegram/_bot.py", line 641, in _do_post
    return await request.post(
           ^^^^^^^^^^^^^^^^^^^
  File "/root/jupyter-env/lib/python3.12/site-packages/telegram/request/_baserequest.py", line 200, in post
    result = await self._request_wrapper(
             ^^^^^^^^^^^^^^^^^^^^^^^^^^^^
  File "/root/jupyter-env/lib/python3.12/site-packages/telegram/request/_baserequest.py", line 340, in _request_wrapper
    raise exc
  File "/root/jupyter-env/lib/python3.12/site-packages/telegram/request/_baserequest.py", line 330, in _request_wrapper
    code, payload = await self.do_request(
                    ^^^^^^^^^^^^^^^^^^^^^^
  File "/root/jupyter-env/lib/python3.12/site-packages/telegram/request/_httpxrequest.py", line 292, in do_request
    raise NetworkError(f"httpx.{err.__class__.__name__}: {err}") from err
telegram.error.NetworkError: httpx.ReadError: 
/root/jupyter-env/lib/python3.12/site-packages/urllib3/connectionpool.py:1097: InsecureRequestWarning: Unverified HTTPS request is being made to host '193.187.174.24'. Adding certificate verification is strongly advised. See: https://urllib3.readthedocs.io/en/latest/advanced-usage.html#tls-warnings
  warnings.warn(
